Workbook

Sheet Wet-Dry Months
AK1: F | AL1: -1 | AM1: 1 | AP1: =L2 -> 0.3
D2: Sorted by 1 | F2: Sorted by 2 | K2: StDev +/- | L2: 0.3 | N2: Summary (using Mean) | T2: Month | U2: Max | V2: Year | X2: Min | Y2: Year | AA2: Median | AG2: Ref | AK2: Average | AL2: Year Just Below | AM2: Year Just Above | AO2: St Dev | AP2: Average | AR2: Median
A3: month count | B3: cumu count | C3: time | D3: month | E3: mean | F3: mean_nans | G3: year | H3: WDA - AVG | I3: WDA - MEDIAN | N3: Month | O3: Wet | P3: Avg | Q3: Dry | R3: Total | AA3: Cumulative | AB3: High R23 | AD3: Low R24 | AE3: Year | AP3: Low | AQ3: High | AR3: Low | AS3: High
A4: =IF(D4=D3,A3+1,1) -> 1 | B4: 1 | C4: 41305 | D4: 1 | E4: 126.02658 | F4: 207.33242 | G4: 2013 | H4: =IF(F4<VLOOKUP($D4,$T$4:$AS$15,23,FALSE),"DRY",IF(F4>VLOOKUP($D4,$T$4:$AS$15,24,FALSE),"WET","AVG")) -> WET | I4: =IF(F4<VLOOKUP($D4,$T$4:$AS$15,25,FALSE),"DRY",IF(F4>VLOOKUP($D4,$T$4:$AS$15,26,FALSE),"WET","AVG")) -> WET | N4: 1 | O4: =COUNTIFS($D$4:$D$541,$N4,$H$4:$H$541,O$3) -> 7 | P4: =COUNTIFS($D$4:$D$541,$N4,$H$4:$H$541,P$3) -> 4 | Q4: =COUNTIFS($D$4:$D$541,$N4,$H$4:$H$541,Q$3) -> 7 | R4: =SUM(O4:Q4) -> 18 | T4: 1 | U4: =_xlfn.MAXIFS($F$4:$F$541,$D$4:$D$541,$T4) -> 207.33242 | V4: =VLOOKUP($U4,$F$4:$G$541,2,FALSE) -> 2013 | X4: =_xlfn.MINIFS($F$4:$F$541,$D$4:$D$541,$T4) -> 58.263549 | Y4: =VLOOKUP($X4,$F$4:$G$541,2,FALSE) -> 2014 | AA4: =COUNTIFS($D$4:$D$541,$T4) -> 18 | AB4: =VLOOKUP($AA4-13,$B$4:$G$541,5,FALSE) -> 145.71685 | AC4: =MEDIAN(INDIRECT(AI4)) -> 109.56885 | AD4: =VLOOKUP($AA4-11,$B$4:$G$541,5,FALSE) -> 138.61486 | AE4: =VLOOKUP(AB4,$F$4:$G$541,2,FALSE)&", "&VLOOKUP(AD4,$F$4:$G$541,2,FALSE) -> 2023, 2015 | AG4: =MATCH(T4,D:D,0) -> 4 | AH4: =AG5-1 -> 21 | AI4: =$AK$1&AG4&":"&$AK$1&AH4 -> F4:F21 | AK4: =AVERAGEIFS($F$4:$F$541,$D$4:$D$541,$T4) -> 118.31086 | AL4: =VLOOKUP(_xlfn.XMATCH($AK4,INDIRECT($AI4),AL$1,1),$A$4:$G$541,7,FALSE) -> 2019 | AM4: =VLOOKUP(_xlfn.XMATCH($AK4,INDIRECT($AI4),AM$1,1),$A$4:$G$541,7,FALSE) -> 2018 | AO4: =STDEV(INDIRECT(AI4)) -> 46.334991 | AP4: =$AK4-($AO4*$AP$1) -> 104.41036 | AQ4: =$AK4+($AO4*$AP$1) -> 132.21136 | AR4: =$AC4-($AO4*$AP$1) -> 95.668352 | AS4: =$AC4+($AO4*$AP$1) -> 123.46935
A5: =IF(D5=D4,A4+1,1) -> 2 | B5: =B4+1 -> 2 | C5: 39478 | D5: 1 | E5: 116.1332 | F5: 191.05634 | G5: 2008 | H5: =IF(F5<VLOOKUP($D5,$T$4:$AS$15,23,FALSE),"DRY",IF(F5>VLOOKUP($D5,$T$4:$AS$15,24,FALSE),"WET","AVG")) -> WET | I5: =IF(F5<VLOOKUP($D5,$T$4:$AS$15,25,FALSE),"DRY",IF(F5>VLOOKUP($D5,$T$4:$AS$15,26,FALSE),"WET","AVG")) -> WET | N5: =N4+1 -> 2 | O5: =COUNTIFS($D$4:$D$541,$N5,$H$4:$H$541,O$3) -> 5 | P5: =COUNTIFS($D$4:$D$541,$N5,$H$4:$H$541,P$3) -> 5 | Q5: =COUNTIFS($D$4:$D$541,$N5,$H$4:$H$541,Q$3) -> 8 | R5: =SUM(O5:Q5) -> 18 | T5: =T4+1 -> 2 | U5: =_xlfn.MAXIFS($F$4:$F$541,$D$4:$D$541,$T5) -> 162.93463 | V5: =VLOOKUP($U5,$F$4:$G$541,2,FALSE) -> 2013 | X5: =_xlfn.MINIFS($F$4:$F$541,$D$4:$D$541,$T5) -> 44.432236 | Y5: =VLOOKUP($X5,$F$4:$G$541,2,FALSE) -> 2007 | AA5: =AA4+COUNTIFS($D$4:$D$541,$T5) -> 36 | AB5: =VLOOKUP($AA5-13,$B$4:$G$541,5,FALSE) -> 142.78507 | AC5: =MEDIAN(INDIRECT(AI5)) -> 90.118146 | AD5: =VLOOKUP($AA5-11,$B$4:$G$541,5,FALSE) -> 98.333631 | AE5: =VLOOKUP(AB5,$F$4:$G$541,2,FALSE)&", "&VLOOKUP(AD5,$F$4:$G$541,2,FALSE) -> 2018, 2021 | AG5: =MATCH(T5,D:D,0) -> 22 | AH5: =AG5+AH4-AG4 -> 39 | AI5: =$AK$1&AG5&":"&$AK$1&AH5 -> F22:F39 | AK5: =AVERAGEIFS($F$4:$F$541,$D$4:$D$541,$T5) -> 96.242471 | AL5: =VLOOKUP(_xlfn.XMATCH($AK5,INDIRECT($AI5),AL$1,1),$A$4:$G$541,7,FALSE) -> 2018 | AM5: =VLOOKUP(_xlfn.XMATCH($AK5,INDIRECT($AI5),AM$1,1),$A$4:$G$541,7,FALSE) -> 2015 | AO5: =STDEV(INDIRECT(AI5)) -> 41.489982 | AP5: =$AK5-($AO5*$AP$1) -> 83.795476 | AQ5: =$AK5+($AO5*$AP$1) -> 108.68947 | AR5: =$AC5-($AO5*$AP$1) -> 77.671151 | AS5: =$AC5+($AO5*$AP$1) -> 102.56514
A6: =IF(D6=D5,A5+1,1) -> 3 | B6: =B5+1 -> 3 | C6: 39113 | D6: 1 | E6: 105.53181 | F6: 173.61548 | G6: 2007 | H6: =IF(F6<VLOOKUP($D6,$T$4:$AS$15,23,FALSE),"DRY",IF(F6>VLOOKUP($D6,$T$4:$AS$15,24,FALSE),"WET","AVG")) -> WET | I6: =IF(F6<VLOOKUP($D6,$T$4:$AS$15,25,FALSE),"DRY",IF(F6>VLOOKUP($D6,$T$4:$AS$15,26,FALSE),"WET","AVG")) -> WET | N6: =N5+1 -> 3 | O6: =COUNTIFS($D$4:$D$541,$N6,$H$4:$H$541,O$3) -> 5 | P6: =COUNTIFS($D$4:$D$541,$N6,$H$4:$H$541,P$3) -> 5 | Q6: =COUNTIFS($D$4:$D$541,$N6,$H$4:$H$541,Q$3) -> 8 | R6: =SUM(O6:Q6) -> 18 | T6: =T5+1 -> 3 | U6: =_xlfn.MAXIFS($F$4:$F$541,$D$4:$D$541,$T6) -> 190.13472 | V6: =VLOOKUP($U6,$F$4:$G$541,2,FALSE) -> 2009 | X6: =_xlfn.MINIFS($F$4:$F$541,$D$4:$D$541,$T6) -> 24.008024 | Y6: =VLOOKUP($X6,$F$4:$G$541,2,FALSE) -> 2006 | AA6: =AA5+COUNTIFS($D$4:$D$541,$T6) -> 54 | AB6: =VLOOKUP($AA6-13,$B$4:$G$541,5,FALSE) -> 142.92896 | AC6: =MEDIAN(INDIRECT(AI6)) -> 96.156 | AD6: =VLOOKUP($AA6-11,$B$4:$G$541,5,FALSE) -> 108.64417 | AE6: =VLOOKUP(AB6,$F$4:$G$541,2,FALSE)&", "&VLOOKUP(AD6,$F$4:$G$541,2,FALSE) -> 2015, 2022 | AG6: =MATCH(T6,D:D,0) -> 40 | AH6: =AG6+AH5-AG5 -> 57 | AI6: =$AK$1&AG6&":"&$AK$1&AH6 -> F40:F57 | AK6: =AVERAGEIFS($F$4:$F$541,$D$4:$D$541,$T6) -> 98.824215 | AL6: =VLOOKUP(_xlfn.XMATCH($AK6,INDIRECT($AI6),AL$1,1),$A$4:$G$541,7,FALSE) -> 2019 | AM6: =VLOOKUP(_xlfn.XMATCH($AK6,INDIRECT($AI6),AM$1,1),$A$4:$G$541,7,FALSE) -> 2018 | AO6: =STDEV(INDIRECT(AI6)) -> 50.59606 | AP6: =$AK6-($AO6*$AP$1) -> 83.645398 | AQ6: =$AK6+($AO6*$AP$1) -> 114.00303 | AR6: =$AC6-($AO6*$AP$1) -> 80.977183 | AS6: =$AC6+($AO6*$AP$1) -> 111.33482
A7: =IF(D7=D6,A6+1,1) -> 4 | B7: =B6+1 -> 4 | C7: 42766 | D7: 1 | E7: 99.918772 | F7: 164.3812 | G7: 2017 | H7: =IF(F7<VLOOKUP($D7,$T$4:$AS$15,23,FALSE),"DRY",IF(F7>VLOOKUP($D7,$T$4:$AS$15,24,FALSE),"WET","AVG")) -> WET | I7: =IF(F7<VLOOKUP($D7,$T$4:$AS$15,25,FALSE),"DRY",IF(F7>VLOOKUP($D7,$T$4:$AS$15,26,FALSE),"WET","AVG")) -> WET | K7: Mean of wet Januarys = 161.64 mm , therefore Jan 2017 is the closest and therefore is our "representativly wet January" with a rainfall depth of 164.38 mm | N7: =N6+1 -> 4 | O7: =COUNTIFS($D$4:$D$541,$N7,$H$4:$H$541,O$3) -> 6 | P7: =COUNTIFS($D$4:$D$541,$N7,$H$4:$H$541,P$3) -> 7 | Q7: =COUNTIFS($D$4:$D$541,$N7,$H$4:$H$541,Q$3) -> 5 | R7: =SUM(O7:Q7) -> 18 | T7: =T6+1 -> 4 | U7: =_xlfn.MAXIFS($F$4:$F$541,$D$4:$D$541,$T7) -> 250.79478 | V7: =VLOOKUP($U7,$F$4:$G$541,2,FALSE) -> 2015 | X7: =_xlfn.MINIFS($F$4:$F$541,$D$4:$D$541,$T7) -> 29.617459 | Y7: =VLOOKUP($X7,$F$4:$G$541,2,FALSE) -> 2010 | AA7: =AA6+COUNTIFS($D$4:$D$541,$T7) -> 72 | AB7: =VLOOKUP($AA7-13,$B$4:$G$541,5,FALSE) -> 166.56473 | AC7: =MEDIAN(INDIRECT(AI7)) -> 118.12686 | AD7: =VLOOKUP($AA7-11,$B$4:$G$541,5,FALSE) -> 122.58232 | AE7: =VLOOKUP(AB7,$F$4:$G$541,2,FALSE)&", "&VLOOKUP(AD7,$F$4:$G$541,2,FALSE) -> 2013, 2017 | AG7: =MATCH(T7,D:D,0) -> 58 | AH7: =AG7+AH6-AG6 -> 75 | AI7: =$AK$1&AG7&":"&$AK$1&AH7 -> F58:F75 | AK7: =AVERAGEIFS($F$4:$F$541,$D$4:$D$541,$T7) -> 126.00338 | AL7: =VLOOKUP(_xlfn.XMATCH($AK7,INDIRECT($AI7),AL$1,1),$A$4:$G$541,7,FALSE) -> 2015 | AM7: =VLOOKUP(_xlfn.XMATCH($AK7,INDIRECT($AI7),AM$1,1),$A$4:$G$541,7,FALSE) -> 2020 | AO7: =STDEV(INDIRECT(AI7)) -> 57.96207 | AP7: =$AK7-($AO7*$AP$1) -> 108.61476 | AQ7: =$AK7+($AO7*$AP$1) -> 143.392 | AR7: =$AC7-($AO7*$AP$1) -> 100.73824 | AS7: =$AC7+($AO7*$AP$1) -> 135.51548
A8: =IF(D8=D7,A7+1,1) -> 5 | B8: =B7+1 -> 5 | C8: 44957 | D8: 1 | E8: 88.573684 | F8: 145.71685 | G8: 2023 | H8: =IF(F8<VLOOKUP($D8,$T$4:$AS$15,23,FALSE),"DRY",IF(F8>VLOOKUP($D8,$T$4:$AS$15,24,FALSE),"WET","AVG")) -> WET | I8: =IF(F8<VLOOKUP($D8,$T$4:$AS$15,25,FALSE),"DRY",IF(F8>VLOOKUP($D8,$T$4:$AS$15,26,FALSE),"WET","AVG")) -> WET | N8: =N7+1 -> 5 | O8: =COUNTIFS($D$4:$D$541,$N8,$H$4:$H$541,O$3) -> 6 | P8: =COUNTIFS($D$4:$D$541,$N8,$H$4:$H$541,P$3) -> 5 | Q8: =COUNTIFS($D$4:$D$541,$N8,$H$4:$H$541,Q$3) -> 7 | R8: =SUM(O8:Q8) -> 18 | T8: =T7+1 -> 5 | U8: =_xlfn.MAXIFS($F$4:$F$541,$D$4:$D$541,$T8) -> 273.13365 | V8: =VLOOKUP($U8,$F$4:$G$541,2,FALSE) -> 2021 | X8: =_xlfn.MINIFS($F$4:$F$541,$D$4:$D$541,$T8) -> 31.000427 | Y8: =VLOOKUP($X8,$F$4:$G$541,2,FALSE) -> 2011 | AA8: =AA7+COUNTIFS($D$4:$D$541,$T8) -> 90 | AB8: =VLOOKUP($AA8-13,$B$4:$G$541,5,FALSE) -> 172.63136 | AC8: =MEDIAN(INDIRECT(AI8)) -> 139.49904 | AD8: =VLOOKUP($AA8-11,$B$4:$G$541,5,FALSE) -> 147.87139 | AE8: =VLOOKUP(AB8,$F$4:$G$541,2,FALSE)&", "&VLOOKUP(AD8,$F$4:$G$541,2,FALSE) -> 2015, 2013 | AG8: =MATCH(T8,D:D,0) -> 76 | AH8: =AG8+AH7-AG7 -> 93 | AI8: =$AK$1&AG8&":"&$AK$1&AH8 -> F76:F93 | AK8: =AVERAGEIFS($F$4:$F$541,$D$4:$D$541,$T8) -> 138.85534 | AL8: =VLOOKUP(_xlfn.XMATCH($AK8,INDIRECT($AI8),AL$1,1),$A$4:$G$541,7,FALSE) -> 2016 | AM8: =VLOOKUP(_xlfn.XMATCH($AK8,INDIRECT($AI8),AM$1,1),$A$4:$G$541,7,FALSE) -> 2019 | AO8: =STDEV(INDIRECT(AI8)) -> 60.661786 | AP8: =$AK8-($AO8*$AP$1) -> 120.6568 | AQ8: =$AK8+($AO8*$AP$1) -> 157.05387 | AR8: =$AC8-($AO8*$AP$1) -> 121.30051 | AS8: =$AC8+($AO8*$AP$1) -> 157.69758
A9: =IF(D9=D8,A8+1,1) -> 6 | B9: =B8+1 -> 6 | C9: 43861 | D9: 1 | E9: 87.441827 | F9: 143.85478 | G9: 2020 | H9: =IF(F9<VLOOKUP($D9,$T$4:$AS$15,23,FALSE),"DRY",IF(F9>VLOOKUP($D9,$T$4:$AS$15,24,FALSE),"WET","AVG")) -> WET | I9: =IF(F9<VLOOKUP($D9,$T$4:$AS$15,25,FALSE),"DRY",IF(F9>VLOOKUP($D9,$T$4:$AS$15,26,FALSE),"WET","AVG")) -> WET | N9: =N8+1 -> 6 | O9: =COUNTIFS($D$4:$D$541,$N9,$H$4:$H$541,O$3) -> 6 | P9: =COUNTIFS($D$4:$D$541,$N9,$H$4:$H$541,P$3) -> 5 | Q9: =COUNTIFS($D$4:$D$541,$N9,$H$4:$H$541,Q$3) -> 7 | R9: =SUM(O9:Q9) -> 18 | T9: =T8+1 -> 6 | U9: =_xlfn.MAXIFS($F$4:$F$541,$D$4:$D$541,$T9) -> 275.65669 | V9: =VLOOKUP($U9,$F$4:$G$541,2,FALSE) -> 2017 | X9: =_xlfn.MINIFS($F$4:$F$541,$D$4:$D$541,$T9) -> 45.408628 | Y9: =VLOOKUP($X9,$F$4:$G$541,2,FALSE) -> 2009 | AA9: =AA8+COUNTIFS($D$4:$D$541,$T9) -> 108 | AB9: =VLOOKUP($AA9-13,$B$4:$G$541,5,FALSE) -> 177.00145 | AC9: =MEDIAN(INDIRECT(AI9)) -> 131.2043 | AD9: =VLOOKUP($AA9-11,$B$4:$G$541,5,FALSE) -> 156.63967 | AE9: =VLOOKUP(AB9,$F$4:$G$541,2,FALSE)&", "&VLOOKUP(AD9,$F$4:$G$541,2,FALSE) -> 2014, 2010 | AG9: =MATCH(T9,D:D,0) -> 94 | AH9: =AG9+AH8-AG8 -> 111 | AI9: =$AK$1&AG9&":"&$AK$1&AH9 -> F94:F111 | AK9: =AVERAGEIFS($F$4:$F$541,$D$4:$D$541,$T9) -> 141.66685 | AL9: =VLOOKUP(_xlfn.XMATCH($AK9,INDIRECT($AI9),AL$1,1),$A$4:$G$541,7,FALSE) -> 2018 | AM9: =VLOOKUP(_xlfn.XMATCH($AK9,INDIRECT($AI9),AM$1,1),$A$4:$G$541,7,FALSE) -> 2015 | AO9: =STDEV(INDIRECT(AI9)) -> 59.201812 | AP9: =$AK9-($AO9*$AP$1) -> 123.90631 | AQ9: =$AK9+($AO9*$AP$1) -> 159.4274 | AR9: =$AC9-($AO9*$AP$1) -> 113.44376 | AS9: =$AC9+($AO9*$AP$1) -> 148.96484
A10: =IF(D10=D9,A9+1,1) -> 7 | B10: =B9+1 -> 7 | C10: 42035 | D10: 1 | E10: 84.256752 | F10: 138.61486 | G10: 2015 | H10: =IF(F10<VLOOKUP($D10,$T$4:$AS$15,23,FALSE),"DRY",IF(F10>VLOOKUP($D10,$T$4:$AS$15,24,FALSE),"WET","AVG")) -> WET | I10: =IF(F10<VLOOKUP($D10,$T$4:$AS$15,25,FALSE),"DRY",IF(F10>VLOOKUP($D10,$T$4:$AS$15,26,FALSE),"WET","AVG")) -> WET | N10: =N9+1 -> 7 | O10: =COUNTIFS($D$4:$D$541,$N10,$H$4:$H$541,O$3) -> 9 | P10: =COUNTIFS($D$4:$D$541,$N10,$H$4:$H$541,P$3) -> 2 | Q10: =COUNTIFS($D$4:$D$541,$N10,$H$4:$H$541,Q$3) -> 7 | R10: =SUM(O10:Q10) -> 18 | T10: =T9+1 -> 7 | U10: =_xlfn.MAXIFS($F$4:$F$541,$D$4:$D$541,$T10) -> 227.10926 | V10: =VLOOKUP($U10,$F$4:$G$541,2,FALSE) -> 2020 | X10: =_xlfn.MINIFS($F$4:$F$541,$D$4:$D$541,$T10) -> 80.501379 | Y10: =VLOOKUP($X10,$F$4:$G$541,2,FALSE) -> 2015 | AA10: =AA9+COUNTIFS($D$4:$D$541,$T10) -> 126 | AB10: =VLOOKUP($AA10-13,$B$4:$G$541,5,FALSE) -> 216.98352 | AC10: =MEDIAN(INDIRECT(AI10)) -> 178.56253 | AD10: =VLOOKUP($AA10-11,$B$4:$G$541,5,FALSE) -> 209.46012 | AE10: =VLOOKUP(AB10,$F$4:$G$541,2,FALSE)&", "&VLOOKUP(AD10,$F$4:$G$541,2,FALSE) -> 2011, 2006 | AG10: =MATCH(T10,D:D,0) -> 112 | AH10: =AG10+AH9-AG9 -> 129 | AI10: =$AK$1&AG10&":"&$AK$1&AH10 -> F112:F129 | AK10: =AVERAGEIFS($F$4:$F$541,$D$4:$D$541,$T10) -> 171.75583 | AL10: =VLOOKUP(_xlfn.XMATCH($AK10,INDIRECT($AI10),AL$1,1),$A$4:$G$541,7,FALSE) -> 2016 | AM10: =VLOOKUP(_xlfn.XMATCH($AK10,INDIRECT($AI10),AM$1,1),$A$4:$G$541,7,FALSE) -> 2019 | AO10: =STDEV(INDIRECT(AI10)) -> 48.29998 | AP10: =$AK10-($AO10*$AP$1) -> 157.26584 | AQ10: =$AK10+($AO10*$AP$1) -> 186.24583 | AR10: =$AC10-($AO10*$AP$1) -> 164.07254 | AS10: =$AC10+($AO10*$AP$1) -> 193.05252
A11: =IF(D11=D10,A10+1,1) -> 8 | B11: =B10+1 -> 8 | C11: 43131 | D11: 1 | E11: 78.14407 | F11: 128.55859 | G11: 2018 | H11: =IF(F11<VLOOKUP($D11,$T$4:$AS$15,23,FALSE),"DRY",IF(F11>VLOOKUP($D11,$T$4:$AS$15,24,FALSE),"WET","AVG")) -> AVG | I11: =IF(F11<VLOOKUP($D11,$T$4:$AS$15,25,FALSE),"DRY",IF(F11>VLOOKUP($D11,$T$4:$AS$15,26,FALSE),"WET","AVG")) -> WET | N11: =N10+1 -> 8 | O11: =COUNTIFS($D$4:$D$541,$N11,$H$4:$H$541,O$3) -> 6 | P11: =COUNTIFS($D$4:$D$541,$N11,$H$4:$H$541,P$3) -> 3 | Q11: =COUNTIFS($D$4:$D$541,$N11,$H$4:$H$541,Q$3) -> 9 | R11: =SUM(O11:Q11) -> 18 | T11: =T10+1 -> 8 | U11: =_xlfn.MAXIFS($F$4:$F$541,$D$4:$D$541,$T11) -> 447.03936 | V11: =VLOOKUP($U11,$F$4:$G$541,2,FALSE) -> 2017 | X11: =_xlfn.MINIFS($F$4:$F$541,$D$4:$D$541,$T11) -> 41.700172 | Y11: =VLOOKUP($X11,$F$4:$G$541,2,FALSE) -> 2023 | AA11: =AA10+COUNTIFS($D$4:$D$541,$T11) -> 144 | AB11: =VLOOKUP($AA11-13,$B$4:$G$541,5,FALSE) -> 246.94706 | AC11: =MEDIAN(INDIRECT(AI11)) -> 166.96167 | AD11: =VLOOKUP($AA11-11,$B$4:$G$541,5,FALSE) -> 208.45175 | AE11: =VLOOKUP(AB11,$F$4:$G$541,2,FALSE)&", "&VLOOKUP(AD11,$F$4:$G$541,2,FALSE) -> 2021, 2010 | AG11: =MATCH(T11,D:D,0) -> 130 | AH11: =AG11+AH10-AG10 -> 147 | AI11: =$AK$1&AG11&":"&$AK$1&AH11 -> F130:F147 | AK11: =AVERAGEIFS($F$4:$F$541,$D$4:$D$541,$T11) -> 185.69022 | AL11: =VLOOKUP(_xlfn.XMATCH($AK11,INDIRECT($AI11),AL$1,1),$A$4:$G$541,7,FALSE) -> 2019 | AM11: =VLOOKUP(_xlfn.XMATCH($AK11,INDIRECT($AI11),AM$1,1),$A$4:$G$541,7,FALSE) -> 2018 | AO11: =STDEV(INDIRECT(AI11)) -> 101.97245 | AP11: =$AK11-($AO11*$AP$1) -> 155.09849 | AQ11: =$AK11+($AO11*$AP$1) -> 216.28196 | AR11: =$AC11-($AO11*$AP$1) -> 136.36993 | AS11: =$AC11+($AO11*$AP$1) -> 197.5534
A12: =IF(D12=D11,A11+1,1) -> 9 | B12: =B11+1 -> 9 | C12: 43496 | D12: 1 | E12: 67.666736 | F12: 111.32182 | G12: 2019 | H12: =IF(F12<VLOOKUP($D12,$T$4:$AS$15,23,FALSE),"DRY",IF(F12>VLOOKUP($D12,$T$4:$AS$15,24,FALSE),"WET","AVG")) -> AVG | I12: =IF(F12<VLOOKUP($D12,$T$4:$AS$15,25,FALSE),"DRY",IF(F12>VLOOKUP($D12,$T$4:$AS$15,26,FALSE),"WET","AVG")) -> AVG | N12: =N11+1 -> 9 | O12: =COUNTIFS($D$4:$D$541,$N12,$H$4:$H$541,O$3) -> 5 | P12: =COUNTIFS($D$4:$D$541,$N12,$H$4:$H$541,P$3) -> 4 | Q12: =COUNTIFS($D$4:$D$541,$N12,$H$4:$H$541,Q$3) -> 9 | R12: =SUM(O12:Q12) -> 18 | T12: =T11+1 -> 9 | U12: =_xlfn.MAXIFS($F$4:$F$541,$D$4:$D$541,$T12) -> 254.54711 | V12: =VLOOKUP($U12,$F$4:$G$541,2,FALSE) -> 2018 | X12: =_xlfn.MINIFS($F$4:$F$541,$D$4:$D$541,$T12) -> 34.380561 | Y12: =VLOOKUP($X12,$F$4:$G$541,2,FALSE) -> 2017 | AA12: =AA11+COUNTIFS($D$4:$D$541,$T12) -> 162 | AB12: =VLOOKUP($AA12-13,$B$4:$G$541,5,FALSE) -> 167.97721 | AC12: =MEDIAN(INDIRECT(AI12)) -> 118.38999 | AD12: =VLOOKUP($AA12-11,$B$4:$G$541,5,FALSE) -> 133.65835 | AE12: =VLOOKUP(AB12,$F$4:$G$541,2,FALSE)&", "&VLOOKUP(AD12,$F$4:$G$541,2,FALSE) -> 2009, 2007 | AG12: =MATCH(T12,D:D,0) -> 148 | AH12: =AG12+AH11-AG11 -> 165 | AI12: =$AK$1&AG12&":"&$AK$1&AH12 -> F148:F165 | AK12: =AVERAGEIFS($F$4:$F$541,$D$4:$D$541,$T12) -> 134.09156 | AL12: =VLOOKUP(_xlfn.XMATCH($AK12,INDIRECT($AI12),AL$1,1),$A$4:$G$541,7,FALSE) -> 2015 | AM12: =VLOOKUP(_xlfn.XMATCH($AK12,INDIRECT($AI12),AM$1,1),$A$4:$G$541,7,FALSE) -> 2020 | AO12: =STDEV(INDIRECT(AI12)) -> 67.184475 | AP12: =$AK12-($AO12*$AP$1) -> 113.93621 | AQ12: =$AK12+($AO12*$AP$1) -> 154.2469 | AR12: =$AC12-($AO12*$AP$1) -> 98.234648 | AS12: =$AC12+($AO12*$AP$1) -> 138.54533
A13: =IF(D13=D12,A12+1,1) -> 10 | B13: =B12+1 -> 10 | C13: 42400 | D13: 1 | E13: 65.535659 | F13: 107.81588 | G13: 2016 | H13: =IF(F13<VLOOKUP($D13,$T$4:$AS$15,23,FALSE),"DRY",IF(F13>VLOOKUP($D13,$T$4:$AS$15,24,FALSE),"WET","AVG")) -> AVG | I13: =IF(F13<VLOOKUP($D13,$T$4:$AS$15,25,FALSE),"DRY",IF(F13>VLOOKUP($D13,$T$4:$AS$15,26,FALSE),"WET","AVG")) -> AVG | N13: =N12+1 -> 10 | O13: =COUNTIFS($D$4:$D$541,$N13,$H$4:$H$541,O$3) -> 6 | P13: =COUNTIFS($D$4:$D$541,$N13,$H$4:$H$541,P$3) -> 4 | Q13: =COUNTIFS($D$4:$D$541,$N13,$H$4:$H$541,Q$3) -> 8 | R13: =SUM(O13:Q13) -> 18 | T13: =T12+1 -> 10 | U13: =_xlfn.MAXIFS($F$4:$F$541,$D$4:$D$541,$T13) -> 263.0213 | V13: =VLOOKUP($U13,$F$4:$G$541,2,FALSE) -> 2009 | X13: =_xlfn.MINIFS($F$4:$F$541,$D$4:$D$541,$T13) -> 6.083875 | Y13: =VLOOKUP($X13,$F$4:$G$541,2,FALSE) -> 2016 | AA13: =AA12+COUNTIFS($D$4:$D$541,$T13) -> 180 | AB13: =VLOOKUP($AA13-13,$B$4:$G$541,5,FALSE) -> 149.24153 | AC13: =MEDIAN(INDIRECT(AI13)) -> 91.690941 | AD13: =VLOOKUP($AA13-11,$B$4:$G$541,5,FALSE) -> 122.27085 | AE13: =VLOOKUP(AB13,$F$4:$G$541,2,FALSE)&", "&VLOOKUP(AD13,$F$4:$G$541,2,FALSE) -> 2020, 2017 | AG13: =MATCH(T13,D:D,0) -> 166 | AH13: =AG13+AH12-AG12 -> 183 | AI13: =$AK$1&AG13&":"&$AK$1&AH13 -> F166:F183 | AK13: =AVERAGEIFS($F$4:$F$541,$D$4:$D$541,$T13) -> 105.83678 | AL13: =VLOOKUP(_xlfn.XMATCH($AK13,INDIRECT($AI13),AL$1,1),$A$4:$G$541,7,FALSE) -> 2019 | AM13: =VLOOKUP(_xlfn.XMATCH($AK13,INDIRECT($AI13),AM$1,1),$A$4:$G$541,7,FALSE) -> 2018 | AO13: =STDEV(INDIRECT(AI13)) -> 82.003182 | AP13: =$AK13-($AO13*$AP$1) -> 81.235829 | AQ13: =$AK13+($AO13*$AP$1) -> 130.43774 | AR13: =$AC13-($AO13*$AP$1) -> 67.089986 | AS13: =$AC13+($AO13*$AP$1) -> 116.2919
A14: =IF(D14=D13,A13+1,1) -> 11 | B14: =B13+1 -> 11 | C14: 40574 | D14: 1 | E14: 63.903475 | F14: 105.13069 | G14: 2011 | H14: =IF(F14<VLOOKUP($D14,$T$4:$AS$15,23,FALSE),"DRY",IF(F14>VLOOKUP($D14,$T$4:$AS$15,24,FALSE),"WET","AVG")) -> AVG | I14: =IF(F14<VLOOKUP($D14,$T$4:$AS$15,25,FALSE),"DRY",IF(F14>VLOOKUP($D14,$T$4:$AS$15,26,FALSE),"WET","AVG")) -> AVG | K14: Mean of avg Januarys = 106.17 mm , therefore Jan 2011 is the closest and therefore is our "representativly avg January" with 105.13 | N14: =N13+1 -> 11 | O14: =COUNTIFS($D$4:$D$541,$N14,$H$4:$H$541,O$3) -> 4 | P14: =COUNTIFS($D$4:$D$541,$N14,$H$4:$H$541,P$3) -> 6 | Q14: =COUNTIFS($D$4:$D$541,$N14,$H$4:$H$541,Q$3) -> 8 | R14: =SUM(O14:Q14) -> 18 | T14: =T13+1 -> 11 | U14: =_xlfn.MAXIFS($F$4:$F$541,$D$4:$D$541,$T14) -> 179.09815 | V14: =VLOOKUP($U14,$F$4:$G$541,2,FALSE) -> 2022 | X14: =_xlfn.MINIFS($F$4:$F$541,$D$4:$D$541,$T14) -> 27.182445 | Y14: =VLOOKUP($X14,$F$4:$G$541,2,FALSE) -> 2021 | AA14: =AA13+COUNTIFS($D$4:$D$541,$T14) -> 198 | AB14: =VLOOKUP($AA14-13,$B$4:$G$541,5,FALSE) -> 88.044002 | AC14: =MEDIAN(INDIRECT(AI14)) -> 70.503891 | AD14: =VLOOKUP($AA14-11,$B$4:$G$541,5,FALSE) -> 84.164378 | AE14: =VLOOKUP(AB14,$F$4:$G$541,2,FALSE)&", "&VLOOKUP(AD14,$F$4:$G$541,2,FALSE) -> 2007, 2006 | AG14: =MATCH(T14,D:D,0) -> 184 | AH14: =AG14+AH13-AG13 -> 201 | AI14: =$AK$1&AG14&":"&$AK$1&AH14 -> F184:F201 | AK14: =AVERAGEIFS($F$4:$F$541,$D$4:$D$541,$T14) -> 83.71122 | AL14: =VLOOKUP(_xlfn.XMATCH($AK14,INDIRECT($AI14),AL$1,1),$A$4:$G$541,7,FALSE) -> 2018 | AM14: =VLOOKUP(_xlfn.XMATCH($AK14,INDIRECT($AI14),AM$1,1),$A$4:$G$541,7,FALSE) -> 2015 | AO14: =STDEV(INDIRECT(AI14)) -> 45.834957 | AP14: =$AK14-($AO14*$AP$1) -> 69.960732 | AQ14: =$AK14+($AO14*$AP$1) -> 97.461707 | AR14: =$AC14-($AO14*$AP$1) -> 56.753404 | AS14: =$AC14+($AO14*$AP$1) -> 84.254378
A15: =IF(D15=D14,A14+1,1) -> 12 | B15: =B14+1 -> 12 | C15: 40939 | D15: 1 | E15: 61.046892 | F15: 100.43119 | G15: 2012 | H15: =IF(F15<VLOOKUP($D15,$T$4:$AS$15,23,FALSE),"DRY",IF(F15>VLOOKUP($D15,$T$4:$AS$15,24,FALSE),"WET","AVG")) -> DRY | I15: =IF(F15<VLOOKUP($D15,$T$4:$AS$15,25,FALSE),"DRY",IF(F15>VLOOKUP($D15,$T$4:$AS$15,26,FALSE),"WET","AVG")) -> AVG | N15: =N14+1 -> 12 | O15: =COUNTIFS($D$4:$D$541,$N15,$H$4:$H$541,O$3) -> 6 | P15: =COUNTIFS($D$4:$D$541,$N15,$H$4:$H$541,P$3) -> 4 | Q15: =COUNTIFS($D$4:$D$541,$N15,$H$4:$H$541,Q$3) -> 8 | R15: =SUM(O15:Q15) -> 18 | T15: =T14+1 -> 12 | U15: =_xlfn.MAXIFS($F$4:$F$541,$D$4:$D$541,$T15) -> 307.01961 | V15: =VLOOKUP($U15,$F$4:$G$541,2,FALSE) -> 2009 | X15: =_xlfn.MINIFS($F$4:$F$541,$D$4:$D$541,$T15) -> 64.7574 | Y15: =VLOOKUP($X15,$F$4:$G$541,2,FALSE) -> 2010 | AA15: =AA14+COUNTIFS($D$4:$D$541,$T15) -> 216 | AB15: =VLOOKUP($AA15-13,$B$4:$G$541,5,FALSE) -> 159.90167 | AC15: =MEDIAN(INDIRECT(AI15)) -> 116.88011 | AD15: =VLOOKUP($AA15-11,$B$4:$G$541,5,FALSE) -> 146.871 | AE15: =VLOOKUP(AB15,$F$4:$G$541,2,FALSE)&", "&VLOOKUP(AD15,$F$4:$G$541,2,FALSE) -> 2022, 2023 | AG15: =MATCH(T15,D:D,0) -> 202 | AH15: =AG15+AH14-AG14 -> 219 | AI15: =$AK$1&AG15&":"&$AK$1&AH15 -> F202:F219 | AK15: =AVERAGEIFS($F$4:$F$541,$D$4:$D$541,$T15) -> 131.27368 | AL15: =VLOOKUP(_xlfn.XMATCH($AK15,INDIRECT($AI15),AL$1,1),$A$4:$G$541,7,FALSE) -> 2018 | AM15: =VLOOKUP(_xlfn.XMATCH($AK15,INDIRECT($AI15),AM$1,1),$A$4:$G$541,7,FALSE) -> 2015 | AO15: =STDEV(INDIRECT(AI15)) -> 61.68725 | AP15: =$AK15-($AO15*$AP$1) -> 112.76751 | AQ15: =$AK15+($AO15*$AP$1) -> 149.77986 | AR15: =$AC15-($AO15*$AP$1) -> 98.37393 | AS15: =$AC15+($AO15*$AP$1) -> 135.38628
A16: =IF(D16=D15,A15+1,1) -> 13 | B16: =B15+1 -> 13 | C16: 40209 | D16: 1 | E16: 54.764951 | F16: 90.096467 | G16: 2010 | H16: =IF(F16<VLOOKUP($D16,$T$4:$AS$15,23,FALSE),"DRY",IF(F16>VLOOKUP($D16,$T$4:$AS$15,24,FALSE),"WET","AVG")) -> DRY | I16: =IF(F16<VLOOKUP($D16,$T$4:$AS$15,25,FALSE),"DRY",IF(F16>VLOOKUP($D16,$T$4:$AS$15,26,FALSE),"WET","AVG")) -> DRY
A17: =IF(D17=D16,A16+1,1) -> 14 | B17: =B16+1 -> 14 | C17: 38748 | D17: 1 | E17: 45.684442 | F17: 75.157684 | G17: 2006 | H17: =IF(F17<VLOOKUP($D17,$T$4:$AS$15,23,FALSE),"DRY",IF(F17>VLOOKUP($D17,$T$4:$AS$15,24,FALSE),"WET","AVG")) -> DRY | I17: =IF(F17<VLOOKUP($D17,$T$4:$AS$15,25,FALSE),"DRY",IF(F17>VLOOKUP($D17,$T$4:$AS$15,26,FALSE),"WET","AVG")) -> DRY | N17: Summary (using Median) | T17: 1 | U17: =T17+1 -> 2 | V17: =U17+1 -> 3 | W17: =V17+1 -> 4 | X17: =W17+1 -> 5 | Y17: =X17+1 -> 6 | Z17: =Y17+1 -> 7 | AA17: =Z17+1 -> 8 | AB17: =AA17+1 -> 9 | ... AS17: =AR17+1 -> 26
A18: =IF(D18=D17,A17+1,1) -> 15 | B18: =B17+1 -> 15 | C18: 44592 | D18: 1 | E18: 38.630374 | F18: 63.552695 | G18: 2022 | H18: =IF(F18<VLOOKUP($D18,$T$4:$AS$15,23,FALSE),"DRY",IF(F18>VLOOKUP($D18,$T$4:$AS$15,24,FALSE),"WET","AVG")) -> DRY | I18: =IF(F18<VLOOKUP($D18,$T$4:$AS$15,25,FALSE),"DRY",IF(F18>VLOOKUP($D18,$T$4:$AS$15,26,FALSE),"WET","AVG")) -> DRY | K18: Mean of dry Januarys = 68.63 mm , therefore Jan 2022 is the closest and therefore is our "representativly dry January" with a rainfall depth of 63.55 mm | N18: Month | O18: Wet | P18: Avg | Q18: Dry | R18: Total
A19: =IF(D19=D18,A18+1,1) -> 16 | B19: =B18+1 -> 16 | C19: 44227 | D19: 1 | E19: 38.229242 | F19: 62.892774 | G19: 2021 | H19: =IF(F19<VLOOKUP($D19,$T$4:$AS$15,23,FALSE),"DRY",IF(F19>VLOOKUP($D19,$T$4:$AS$15,24,FALSE),"WET","AVG")) -> DRY | I19: =IF(F19<VLOOKUP($D19,$T$4:$AS$15,25,FALSE),"DRY",IF(F19>VLOOKUP($D19,$T$4:$AS$15,26,FALSE),"WET","AVG")) -> DRY | N19: 1 | O19: =COUNTIFS($D$4:$D$541,$N19,$I$4:$I$541,O$18) -> 8 | P19: =COUNTIFS($D$4:$D$541,$N19,$I$4:$I$541,P$18) -> 4 | Q19: =COUNTIFS($D$4:$D$541,$N19,$I$4:$I$541,Q$18) -> 6 | R19: =SUM(O19:Q19) -> 18 | AB19: Month | AC19: Range
A20: =IF(D20=D19,A19+1,1) -> 17 | B20: =B19+1 -> 17 | C20: 39844 | D20: 1 | E20: 37.566363 | F20: 61.80224 | G20: 2009 | H20: =IF(F20<VLOOKUP($D20,$T$4:$AS$15,23,FALSE),"DRY",IF(F20>VLOOKUP($D20,$T$4:$AS$15,24,FALSE),"WET","AVG")) -> DRY | I20: =IF(F20<VLOOKUP($D20,$T$4:$AS$15,25,FALSE),"DRY",IF(F20>VLOOKUP($D20,$T$4:$AS$15,26,FALSE),"WET","AVG")) -> DRY | N20: =N19+1 -> 2 | O20: =COUNTIFS($D$4:$D$541,$N20,$I$4:$I$541,O$18) -> 5 | P20: =COUNTIFS($D$4:$D$541,$N20,$I$4:$I$541,P$18) -> 5 | Q20: =COUNTIFS($D$4:$D$541,$N20,$I$4:$I$541,Q$18) -> 8 | R20: =SUM(O20:Q20) -> 18 | AB20: -- | AC20: --
A21: =IF(D21=D20,A20+1,1) -> 18 | B21: =B20+1 -> 18 | C21: 41670 | D21: 1 | E21: 35.415377 | F21: 58.263549 | G21: 2014 | H21: =IF(F21<VLOOKUP($D21,$T$4:$AS$15,23,FALSE),"DRY",IF(F21>VLOOKUP($D21,$T$4:$AS$15,24,FALSE),"WET","AVG")) -> DRY | I21: =IF(F21<VLOOKUP($D21,$T$4:$AS$15,25,FALSE),"DRY",IF(F21>VLOOKUP($D21,$T$4:$AS$15,26,FALSE),"WET","AVG")) -> DRY | N21: =N20+1 -> 3 | O21: =COUNTIFS($D$4:$D$541,$N21,$I$4:$I$541,O$18) -> 5 | P21: =COUNTIFS($D$4:$D$541,$N21,$I$4:$I$541,P$18) -> 6 | Q21: =COUNTIFS($D$4:$D$541,$N21,$I$4:$I$541,Q$18) -> 7 | R21: =SUM(O21:Q21) -> 18 | AB21: =T5 -> 2 | AC21: =AB5-AD5 -> 44.451435
A22: =IF(D22=D21,A21+1,1) -> 1 | B22: =B21+1 -> 19 | C22: 41333 | D22: 2 | E22: 99.039478 | F22: 162.93463 | G22: 2013 | H22: =IF(F22<VLOOKUP($D22,$T$4:$AS$15,23,FALSE),"DRY",IF(F22>VLOOKUP($D22,$T$4:$AS$15,24,FALSE),"WET","AVG")) -> WET | I22: =IF(F22<VLOOKUP($D22,$T$4:$AS$15,25,FALSE),"DRY",IF(F22>VLOOKUP($D22,$T$4:$AS$15,26,FALSE),"WET","AVG")) -> WET | N22: =N21+1 -> 4 | O22: =COUNTIFS($D$4:$D$541,$N22,$I$4:$I$541,O$18) -> 6 | P22: =COUNTIFS($D$4:$D$541,$N22,$I$4:$I$541,P$18) -> 7 | Q22: =COUNTIFS($D$4:$D$541,$N22,$I$4:$I$541,Q$18) -> 5 | R22: =SUM(O22:Q22) -> 18 | AB22: =T6 -> 3 | AC22: =AB6-AD6 -> 34.284795
A23: =IF(D23=D22,A22+1,1) -> 2 | B23: =B22+1 -> 20 | C23: 40237 | D23: 2 | E23: 98.702769 | F23: 162.3807 | G23: 2010 | H23: =IF(F23<VLOOKUP($D23,$T$4:$AS$15,23,FALSE),"DRY",IF(F23>VLOOKUP($D23,$T$4:$AS$15,24,FALSE),"WET","AVG")) -> WET | I23: =IF(F23<VLOOKUP($D23,$T$4:$AS$15,25,FALSE),"DRY",IF(F23>VLOOKUP($D23,$T$4:$AS$15,26,FALSE),"WET","AVG")) -> WET | N23: =N22+1 -> 5 | O23: =COUNTIFS($D$4:$D$541,$N23,$I$4:$I$541,O$18) -> 6 | P23: =COUNTIFS($D$4:$D$541,$N23,$I$4:$I$541,P$18) -> 5 | Q23: =COUNTIFS($D$4:$D$541,$N23,$I$4:$I$541,Q$18) -> 7 | R23: =SUM(O23:Q23) -> 18 | AB23: =T7 -> 4 | AC23: =AB7-AD7 -> 43.982403
A24: =IF(D24=D23,A23+1,1) -> 3 | B24: =B23+1 -> 21 | C24: 40968 | D24: 2 | E24: 97.294731 | F24: 160.06426 | G24: 2012 | H24: =IF(F24<VLOOKUP($D24,$T$4:$AS$15,23,FALSE),"DRY",IF(F24>VLOOKUP($D24,$T$4:$AS$15,24,FALSE),"WET","AVG")) -> WET | I24: =IF(F24<VLOOKUP($D24,$T$4:$AS$15,25,FALSE),"DRY",IF(F24>VLOOKUP($D24,$T$4:$AS$15,26,FALSE),"WET","AVG")) -> WET | N24: =N23+1 -> 6 | O24: =COUNTIFS($D$4:$D$541,$N24,$I$4:$I$541,O$18) -> 7 | P24: =COUNTIFS($D$4:$D$541,$N24,$I$4:$I$541,P$18) -> 4 | Q24: =COUNTIFS($D$4:$D$541,$N24,$I$4:$I$541,Q$18) -> 7 | R24: =SUM(O24:Q24) -> 18 | AB24: =T8 -> 5 | AC24: =AB8-AD8 -> 24.759964
A25: =IF(D25=D24,A24+1,1) -> 4 | B25: =B24+1 -> 22 | C25: 41698 | D25: 2 | E25: 91.470652 | F25: 150.48279 | G25: 2014 | H25: =IF(F25<VLOOKUP($D25,$T$4:$AS$15,23,FALSE),"DRY",IF(F25>VLOOKUP($D25,$T$4:$AS$15,24,FALSE),"WET","AVG")) -> WET | I25: =IF(F25<VLOOKUP($D25,$T$4:$AS$15,25,FALSE),"DRY",IF(F25>VLOOKUP($D25,$T$4:$AS$15,26,FALSE),"WET","AVG")) -> WET | N25: =N24+1 -> 7 | O25: =COUNTIFS($D$4:$D$541,$N25,$I$4:$I$541,O$18) -> 8 | P25: =COUNTIFS($D$4:$D$541,$N25,$I$4:$I$541,P$18) -> 3 | Q25: =COUNTIFS($D$4:$D$541,$N25,$I$4:$I$541,Q$18) -> 7 | R25: =SUM(O25:Q25) -> 18 | AB25: =T9 -> 6 | AC25: =AB9-AD9 -> 20.361784
A26: =IF(D26=D25,A25+1,1) -> 5 | B26: =B25+1 -> 23 | C26: 43159 | D26: 2 | E26: 86.791606 | F26: 142.78507 | G26: 2018 | H26: =IF(F26<VLOOKUP($D26,$T$4:$AS$15,23,FALSE),"DRY",IF(F26>VLOOKUP($D26,$T$4:$AS$15,24,FALSE),"WET","AVG")) -> WET | I26: =IF(F26<VLOOKUP($D26,$T$4:$AS$15,25,FALSE),"DRY",IF(F26>VLOOKUP($D26,$T$4:$AS$15,26,FALSE),"WET","AVG")) -> WET | N26: =N25+1 -> 8 | O26: =COUNTIFS($D$4:$D$541,$N26,$I$4:$I$541,O$18) -> 8 | P26: =COUNTIFS($D$4:$D$541,$N26,$I$4:$I$541,P$18) -> 4 | Q26: =COUNTIFS($D$4:$D$541,$N26,$I$4:$I$541,Q$18) -> 6 | R26: =SUM(O26:Q26) -> 18 | AB26: =T10 -> 7 | AC26: =AB10-AD10 -> 7.5234012
A27: =IF(D27=D26,A26+1,1) -> 6 | B27: =B26+1 -> 24 | C27: 38776 | D27: 2 | E27: 60.116169 | F27: 98.900016 | G27: 2006 | H27: =IF(F27<VLOOKUP($D27,$T$4:$AS$15,23,FALSE),"DRY",IF(F27>VLOOKUP($D27,$T$4:$AS$15,24,FALSE),"WET","AVG")) -> AVG | I27: =IF(F27<VLOOKUP($D27,$T$4:$AS$15,25,FALSE),"DRY",IF(F27>VLOOKUP($D27,$T$4:$AS$15,26,FALSE),"WET","AVG")) -> AVG | N27: =N26+1 -> 9 | O27: =COUNTIFS($D$4:$D$541,$N27,$I$4:$I$541,O$18) -> 6 | P27: =COUNTIFS($D$4:$D$541,$N27,$I$4:$I$541,P$18) -> 7 | Q27: =COUNTIFS($D$4:$D$541,$N27,$I$4:$I$541,Q$18) -> 5 | R27: =SUM(O27:Q27) -> 18 | AB27: =T11 -> 8 | AC27: =AB11-AD11 -> 38.495306
A28: =IF(D28=D27,A27+1,1) -> 7 | B28: =B27+1 -> 25 | C28: 44255 | D28: 2 | E28: 59.771894 | F28: 98.333631 | G28: 2021 | H28: =IF(F28<VLOOKUP($D28,$T$4:$AS$15,23,FALSE),"DRY",IF(F28>VLOOKUP($D28,$T$4:$AS$15,24,FALSE),"WET","AVG")) -> AVG | I28: =IF(F28<VLOOKUP($D28,$T$4:$AS$15,25,FALSE),"DRY",IF(F28>VLOOKUP($D28,$T$4:$AS$15,26,FALSE),"WET","AVG")) -> AVG | N28: =N27+1 -> 10 | O28: =COUNTIFS($D$4:$D$541,$N28,$I$4:$I$541,O$18) -> 7 | P28: =COUNTIFS($D$4:$D$541,$N28,$I$4:$I$541,P$18) -> 4 | Q28: =COUNTIFS($D$4:$D$541,$N28,$I$4:$I$541,Q$18) -> 7 | R28: =SUM(O28:Q28) -> 18 | AB28: =T12 -> 9 | AC28: =AB12-AD12 -> 34.318856
A29: =IF(D29=D28,A28+1,1) -> 8 | B29: =B28+1 -> 26 | C29: 43524 | D29: 2 | E29: 55.291441 | F29: 90.962623 | G29: 2019 | H29: =IF(F29<VLOOKUP($D29,$T$4:$AS$15,23,FALSE),"DRY",IF(F29>VLOOKUP($D29,$T$4:$AS$15,24,FALSE),"WET","AVG")) -> AVG | I29: =IF(F29<VLOOKUP($D29,$T$4:$AS$15,25,FALSE),"DRY",IF(F29>VLOOKUP($D29,$T$4:$AS$15,26,FALSE),"WET","AVG")) -> AVG | N29: =N28+1 -> 11 | O29: =COUNTIFS($D$4:$D$541,$N29,$I$4:$I$541,O$18) -> 6 | P29: =COUNTIFS($D$4:$D$541,$N29,$I$4:$I$541,P$18) -> 8 | Q29: =COUNTIFS($D$4:$D$541,$N29,$I$4:$I$541,Q$18) -> 4 | R29: =SUM(O29:Q29) -> 18 | AB29: =T13 -> 10 | AC29: =AB13-AD13 -> 26.970681
A30: =IF(D30=D29,A29+1,1) -> 9 | B30: =B29+1 -> 27 | C30: 39507 | D30: 2 | E30: 55.2226 | F30: 90.849369 | G30: 2008 | H30: =IF(F30<VLOOKUP($D30,$T$4:$AS$15,23,FALSE),"DRY",IF(F30>VLOOKUP($D30,$T$4:$AS$15,24,FALSE),"WET","AVG")) -> AVG | I30: =IF(F30<VLOOKUP($D30,$T$4:$AS$15,25,FALSE),"DRY",IF(F30>VLOOKUP($D30,$T$4:$AS$15,26,FALSE),"WET","AVG")) -> AVG | N30: =N29+1 -> 12 | O30: =COUNTIFS($D$4:$D$541,$N30,$I$4:$I$541,O$18) -> 7 | P30: =COUNTIFS($D$4:$D$541,$N30,$I$4:$I$541,P$18) -> 5 | Q30: =COUNTIFS($D$4:$D$541,$N30,$I$4:$I$541,Q$18) -> 6 | R30: =SUM(O30:Q30) -> 18 | AB30: =T14 -> 11 | AC30: =AB14-AD14 -> 3.8796243
A31: =IF(D31=D30,A30+1,1) -> 10 | B31: =B30+1 -> 28 | C31: 43890 | D31: 2 | E31: 54.333655 | F31: 89.386923 | G31: 2020 | H31: =IF(F31<VLOOKUP($D31,$T$4:$AS$15,23,FALSE),"DRY",IF(F31>VLOOKUP($D31,$T$4:$AS$15,24,FALSE),"WET","AVG")) -> AVG | I31: =IF(F31<VLOOKUP($D31,$T$4:$AS$15,25,FALSE),"DRY",IF(F31>VLOOKUP($D31,$T$4:$AS$15,26,FALSE),"WET","AVG")) -> AVG | AB31: =T15 -> 12 | AC31: =AB15-AD15 -> 13.030665
A32: =IF(D32=D31,A31+1,1) -> 11 | B32: =B31+1 -> 29 | C32: 44985 | D32: 2 | E32: 44.627911 | F32: 73.419533 | G32: 2023 | H32: =IF(F32<VLOOKUP($D32,$T$4:$AS$15,23,FALSE),"DRY",IF(F32>VLOOKUP($D32,$T$4:$AS$15,24,FALSE),"WET","AVG")) -> DRY | I32: =IF(F32<VLOOKUP($D32,$T$4:$AS$15,25,FALSE),"DRY",IF(F32>VLOOKUP($D32,$T$4:$AS$15,26,FALSE),"WET","AVG")) -> DRY
A33: =IF(D33=D32,A32+1,1) -> 12 | B33: =B32+1 -> 30 | C33: 42429 | D33: 2 | E33: 44.561957 | F33: 73.31103 | G33: 2016 | H33: =IF(F33<VLOOKUP($D33,$T$4:$AS$15,23,FALSE),"DRY",IF(F33>VLOOKUP($D33,$T$4:$AS$15,24,FALSE),"WET","AVG")) -> DRY | I33: =IF(F33<VLOOKUP($D33,$T$4:$AS$15,25,FALSE),"DRY",IF(F33>VLOOKUP($D33,$T$4:$AS$15,26,FALSE),"WET","AVG")) -> DRY
A34: =IF(D34=D33,A33+1,1) -> 13 | B34: =B33+1 -> 31 | C34: 39872 | D34: 2 | E34: 44.037762 | F34: 72.448651 | G34: 2009 | H34: =IF(F34<VLOOKUP($D34,$T$4:$AS$15,23,FALSE),"DRY",IF(F34>VLOOKUP($D34,$T$4:$AS$15,24,FALSE),"WET","AVG")) -> DRY | I34: =IF(F34<VLOOKUP($D34,$T$4:$AS$15,25,FALSE),"DRY",IF(F34>VLOOKUP($D34,$T$4:$AS$15,26,FALSE),"WET","AVG")) -> DRY | O34: Avg | P34: Median | Q34: StDev
A35: =IF(D35=D34,A34+1,1) -> 14 | B35: =B34+1 -> 32 | C35: 44620 | D35: 2 | E35: 40.729079 | F35: 67.005376 | G35: 2022 | H35: =IF(F35<VLOOKUP($D35,$T$4:$AS$15,23,FALSE),"DRY",IF(F35>VLOOKUP($D35,$T$4:$AS$15,24,FALSE),"WET","AVG")) -> DRY | I35: =IF(F35<VLOOKUP($D35,$T$4:$AS$15,25,FALSE),"DRY",IF(F35>VLOOKUP($D35,$T$4:$AS$15,26,FALSE),"WET","AVG")) -> DRY | N35: Summary | O35: =AVERAGE(F4:F541) -> 127.68853 | P35: =MEDIAN(F4:F541) -> 116.32461 | Q35: =STDEV(F4:F541) -> 67.393322
A36: =IF(D36=D35,A35+1,1) -> 15 | B36: =B35+1 -> 33 | C36: 42794 | D36: 2 | E36: 32.121767 | F36: 52.845072 | G36: 2017 | H36: =IF(F36<VLOOKUP($D36,$T$4:$AS$15,23,FALSE),"DRY",IF(F36>VLOOKUP($D36,$T$4:$AS$15,24,FALSE),"WET","AVG")) -> DRY | I36: =IF(F36<VLOOKUP($D36,$T$4:$AS$15,25,FALSE),"DRY",IF(F36>VLOOKUP($D36,$T$4:$AS$15,26,FALSE),"WET","AVG")) -> DRY
A37: =IF(D37=D36,A36+1,1) -> 16 | B37: =B36+1 -> 34 | C37: 40602 | D37: 2 | E37: 30.977717 | F37: 50.962939 | G37: 2011 | H37: =IF(F37<VLOOKUP($D37,$T$4:$AS$15,23,FALSE),"DRY",IF(F37>VLOOKUP($D37,$T$4:$AS$15,24,FALSE),"WET","AVG")) -> DRY | I37: =IF(F37<VLOOKUP($D37,$T$4:$AS$15,25,FALSE),"DRY",IF(F37>VLOOKUP($D37,$T$4:$AS$15,26,FALSE),"WET","AVG")) -> DRY
A38: =IF(D38=D37,A37+1,1) -> 17 | B38: =B37+1 -> 35 | C38: 42063 | D38: 2 | E38: 30.91492 | F38: 50.85963 | G38: 2015 | H38: =IF(F38<VLOOKUP($D38,$T$4:$AS$15,23,FALSE),"DRY",IF(F38>VLOOKUP($D38,$T$4:$AS$15,24,FALSE),"WET","AVG")) -> DRY | I38: =IF(F38<VLOOKUP($D38,$T$4:$AS$15,25,FALSE),"DRY",IF(F38>VLOOKUP($D38,$T$4:$AS$15,26,FALSE),"WET","AVG")) -> DRY
A39: =IF(D39=D38,A38+1,1) -> 18 | B39: =B38+1 -> 36 | C39: 39141 | D39: 2 | E39: 27.008042 | F39: 44.432236 | G39: 2007 | H39: =IF(F39<VLOOKUP($D39,$T$4:$AS$15,23,FALSE),"DRY",IF(F39>VLOOKUP($D39,$T$4:$AS$15,24,FALSE),"WET","AVG")) -> DRY | I39: =IF(F39<VLOOKUP($D39,$T$4:$AS$15,25,FALSE),"DRY",IF(F39>VLOOKUP($D39,$T$4:$AS$15,26,FALSE),"WET","AVG")) -> DRY
A40: =IF(D40=D39,A39+1,1) -> 1 | B40: =B39+1 -> 37 | C40: 39903 | D40: 3 | E40: 115.573 | F40: 190.13472 | G40: 2009 | H40: =IF(F40<VLOOKUP($D40,$T$4:$AS$15,23,FALSE),"DRY",IF(F40>VLOOKUP($D40,$T$4:$AS$15,24,FALSE),"WET","AVG")) -> WET | I40: =IF(F40<VLOOKUP($D40,$T$4:$AS$15,25,FALSE),"DRY",IF(F40>VLOOKUP($D40,$T$4:$AS$15,26,FALSE),"WET","AVG")) -> WET
...

Sheet Final Grids
C1: 'Wet-Dry Months'! | E1: F
C2: Ref (from 'Wet-Dry Months' Ref section) | F2: Monthly Conditions Averages (2006 through 2024) | K2: Representative Monthly Values | P2: Date of Corresponding Representative Rainfall
F3: Month | G3: Wet | H3: Avg | I3: Dry | K3: Month | L3: Wet-rep | M3: Avg-rep | N3: Dry-rep | P3: Month | Q3: Wet | R3: Avg | S3: Dry
C4: ='Wet-Dry Months'!AG4 -> 4 | D4: ='Wet-Dry Months'!AH4 -> 21 | E4: =$C$1&'Wet-Dry Months'!AI4 -> 'Wet-Dry Months'!F4:F21 | F4: 1 | G4: =AVERAGEIFS('Wet-Dry Months'!$F$4:$F$541,'Wet-Dry Months'!$I$4:$I$541,'Final Grids'!G$3,'Wet-Dry Months'!$D$4:$D$541,'Final Grids'!$F4) -> 161.64131 | H4: =AVERAGEIFS('Wet-Dry Months'!$F$4:$F$541,'Wet-Dry Months'!$I$4:$I$541,'Final Grids'!H$3,'Wet-Dry Months'!$D$4:$D$541,'Final Grids'!$F4) -> 106.1749 | I4: =AVERAGEIFS('Wet-Dry Months'!$F$4:$F$541,'Wet-Dry Months'!$I$4:$I$541,'Final Grids'!I$3,'Wet-Dry Months'!$D$4:$D$541,'Final Grids'!$F4) -> 68.627568 | K4: 1 | L4: =IF(L42<L74,L26,L58) -> 164.3812 | M4: =IF(M42<M74,M26,M58) -> 105.13069 | N4: =IF(N42<N74,N26,N58) -> 63.552695 | P4: 1 | Q4: =VLOOKUP(L4,'Wet-Dry Months'!$F$3:$G$541,2,FALSE) -> 2017 | R4: =VLOOKUP(M4,'Wet-Dry Months'!$F$3:$G$541,2,FALSE) -> 2011 | S4: =VLOOKUP(N4,'Wet-Dry Months'!$F$3:$G$541,2,FALSE) -> 2022
C5: ='Wet-Dry Months'!AG5 -> 22 | D5: ='Wet-Dry Months'!AH5 -> 39 | E5: =$C$1&'Wet-Dry Months'!AI5 -> 'Wet-Dry Months'!F22:F39 | F5: 2 | G5: =AVERAGEIFS('Wet-Dry Months'!$F$4:$F$541,'Wet-Dry Months'!$I$4:$I$541,'Final Grids'!G$3,'Wet-Dry Months'!$D$4:$D$541,'Final Grids'!$F5) -> 155.72949 | H5: =AVERAGEIFS('Wet-Dry Months'!$F$4:$F$541,'Wet-Dry Months'!$I$4:$I$541,'Final Grids'!H$3,'Wet-Dry Months'!$D$4:$D$541,'Final Grids'!$F5) -> 93.686512 | I5: =AVERAGEIFS('Wet-Dry Months'!$F$4:$F$541,'Wet-Dry Months'!$I$4:$I$541,'Final Grids'!I$3,'Wet-Dry Months'!$D$4:$D$541,'Final Grids'!$F5) -> 60.660558 | K5: 2 | L5: =IF(L43<L75,L27,L59) -> 160.06426 | M5: =IF(M43<M75,M27,M59) -> 90.962623 | N5: =IF(N43<N75,N27,N59) -> 67.005376 | P5: 2 | Q5: =VLOOKUP(L5,'Wet-Dry Months'!$F$3:$G$541,2,FALSE) -> 2012 | R5: =VLOOKUP(M5,'Wet-Dry Months'!$F$3:$G$541,2,FALSE) -> 2019 | S5: =VLOOKUP(N5,'Wet-Dry Months'!$F$3:$G$541,2,FALSE) -> 2022
C6: ='Wet-Dry Months'!AG6 -> 40 | D6: ='Wet-Dry Months'!AH6 -> 57 | E6: =$C$1&'Wet-Dry Months'!AI6 -> 'Wet-Dry Months'!F40:F57 | F6: 3 | G6: =AVERAGEIFS('Wet-Dry Months'!$F$4:$F$541,'Wet-Dry Months'!$I$4:$I$541,'Final Grids'!G$3,'Wet-Dry Months'!$D$4:$D$541,'Final Grids'!$F6) -> 165.45386 | H6: =AVERAGEIFS('Wet-Dry Months'!$F$4:$F$541,'Wet-Dry Months'!$I$4:$I$541,'Final Grids'!H$3,'Wet-Dry Months'!$D$4:$D$541,'Final Grids'!$F6) -> 100.28108 | I6: =AVERAGEIFS('Wet-Dry Months'!$F$4:$F$541,'Wet-Dry Months'!$I$4:$I$541,'Final Grids'!I$3,'Wet-Dry Months'!$D$4:$D$541,'Final Grids'!$F6) -> 49.982872 | K6: 3 | L6: =IF(L44<L76,L28,L60) -> 170.16264 | M6: =IF(M44<M76,M28,M60) -> 97.170449 | N6: =IF(N44<N76,N28,N60) -> 46.289565 | P6: 3 | Q6: =VLOOKUP(L6,'Wet-Dry Months'!$F$3:$G$541,2,FALSE) -> 2012 | R6: =VLOOKUP(M6,'Wet-Dry Months'!$F$3:$G$541,2,FALSE) -> 2017 | S6: =VLOOKUP(N6,'Wet-Dry Months'!$F$3:$G$541,2,FALSE) -> 2019
C7: ='Wet-Dry Months'!AG7 -> 58 | D7: ='Wet-Dry Months'!AH7 -> 75 | E7: =$C$1&'Wet-Dry Months'!AI7 -> 'Wet-Dry Months'!F58:F75 | F7: 4 | G7: =AVERAGEIFS('Wet-Dry Months'!$F$4:$F$541,'Wet-Dry Months'!$I$4:$I$541,'Final Grids'!G$3,'Wet-Dry Months'!$D$4:$D$541,'Final Grids'!$F7) -> 190.19828 | H7: =AVERAGEIFS('Wet-Dry Months'!$F$4:$F$541,'Wet-Dry Months'!$I$4:$I$541,'Final Grids'!H$3,'Wet-Dry Months'!$D$4:$D$541,'Final Grids'!$F7) -> 116.24586 | I7: =AVERAGEIFS('Wet-Dry Months'!$F$4:$F$541,'Wet-Dry Months'!$I$4:$I$541,'Final Grids'!I$3,'Wet-Dry Months'!$D$4:$D$541,'Final Grids'!$F7) -> 62.630033 | K7: 4 | L7: =IF(L45<L77,L29,L61) -> 180.30434 | M7: =IF(M45<M77,M29,M61) -> 117.58415 | N7: =IF(N45<N77,N29,N61) -> 69.717566 | P7: 4 | Q7: =VLOOKUP(L7,'Wet-Dry Months'!$F$3:$G$541,2,FALSE) -> 2016 | R7: =VLOOKUP(M7,'Wet-Dry Months'!$F$3:$G$541,2,FALSE) -> 2014 | S7: =VLOOKUP(N7,'Wet-Dry Months'!$F$3:$G$541,2,FALSE) -> 2022
C8: ='Wet-Dry Months'!AG8 -> 76 | D8: ='Wet-Dry Months'!AH8 -> 93 | E8: =$C$1&'Wet-Dry Months'!AI8 -> 'Wet-Dry Months'!F76:F93 | F8: 5 | G8: =AVERAGEIFS('Wet-Dry Months'!$F$4:$F$541,'Wet-Dry Months'!$I$4:$I$541,'Final Grids'!G$3,'Wet-Dry Months'!$D$4:$D$541,'Final Grids'!$F8) -> 203.87277 | H8: =AVERAGEIFS('Wet-Dry Months'!$F$4:$F$541,'Wet-Dry Months'!$I$4:$I$541,'Final Grids'!H$3,'Wet-Dry Months'!$D$4:$D$541,'Final Grids'!$F8) -> 141.28629 | I8: =AVERAGEIFS('Wet-Dry Months'!$F$4:$F$541,'Wet-Dry Months'!$I$4:$I$541,'Final Grids'!I$3,'Wet-Dry Months'!$D$4:$D$541,'Final Grids'!$F8) -> 81.389706 | K8: 5 | L8: =IF(L46<L78,L30,L62) -> 193.09739 | M8: =IF(M46<M78,M30,M62) -> 141.80287 | N8: =IF(N46<N78,N30,N62) -> 86.080788 | P8: 5 | Q8: =VLOOKUP(L8,'Wet-Dry Months'!$F$3:$G$541,2,FALSE) -> 2019 | R8: =VLOOKUP(M8,'Wet-Dry Months'!$F$3:$G$541,2,FALSE) -> 2020 | S8: =VLOOKUP(N8,'Wet-Dry Months'!$F$3:$G$541,2,FALSE) -> 2012
C9: ='Wet-Dry Months'!AG9 -> 94 | D9: ='Wet-Dry Months'!AH9 -> 111 | E9: =$C$1&'Wet-Dry Months'!AI9 -> 'Wet-Dry Months'!F94:F111 | F9: 6 | G9: =AVERAGEIFS('Wet-Dry Months'!$F$4:$F$541,'Wet-Dry Months'!$I$4:$I$541,'Final Grids'!G$3,'Wet-Dry Months'!$D$4:$D$541,'Final Grids'!$F9) -> 200.34376 | H9: =AVERAGEIFS('Wet-Dry Months'!$F$4:$F$541,'Wet-Dry Months'!$I$4:$I$541,'Final Grids'!H$3,'Wet-Dry Months'!$D$4:$D$541,'Final Grids'!$F9) -> 132.82404 | I9: =AVERAGEIFS('Wet-Dry Months'!$F$4:$F$541,'Wet-Dry Months'!$I$4:$I$541,'Final Grids'!I$3,'Wet-Dry Months'!$D$4:$D$541,'Final Grids'!$F9) -> 88.042982 | K9: 6 | L9: =IF(L47<L79,L31,L63) -> 192.05579 | M9: =IF(M47<M79,M31,M63) -> 132.55115 | N9: =IF(N47<N79,N31,N63) -> 84.480906 | P9: 6 | Q9: =VLOOKUP(L9,'Wet-Dry Months'!$F$3:$G$541,2,FALSE) -> 2019 | R9: =VLOOKUP(M9,'Wet-Dry Months'!$F$3:$G$541,2,FALSE) -> 2018 | S9: =VLOOKUP(N9,'Wet-Dry Months'!$F$3:$G$541,2,FALSE) -> 2011
C10: ='Wet-Dry Months'!AG10 -> 112 | D10: ='Wet-Dry Months'!AH10 -> 129 | E10: =$C$1&'Wet-Dry Months'!AI10 -> 'Wet-Dry Months'!F112:F129 | F10: 7 | G10: =AVERAGEIFS('Wet-Dry Months'!$F$4:$F$541,'Wet-Dry Months'!$I$4:$I$541,'Final Grids'!G$3,'Wet-Dry Months'!$D$4:$D$541,'Final Grids'!$F10) -> 216.90851 | H10: =AVERAGEIFS('Wet-Dry Months'!$F$4:$F$541,'Wet-Dry Months'!$I$4:$I$541,'Final Grids'!H$3,'Wet-Dry Months'!$D$4:$D$541,'Final Grids'!$F10) -> 174.02729 | I10: =AVERAGEIFS('Wet-Dry Months'!$F$4:$F$541,'Wet-Dry Months'!$I$4:$I$541,'Final Grids'!I$3,'Wet-Dry Months'!$D$4:$D$541,'Final Grids'!$F10) -> 119.1793 | K10: 7 | L10: =IF(L48<L80,L32,L64) -> 216.98352 | M10: =IF(M48<M80,M32,M64) -> 168.92453 | N10: =IF(N48<N80,N32,N64) -> 128.01323 | P10: 7 | Q10: =VLOOKUP(L10,'Wet-Dry Months'!$F$3:$G$541,2,FALSE) -> 2011 | R10: =VLOOKUP(M10,'Wet-Dry Months'!$F$3:$G$541,2,FALSE) -> 2014 | S10: =VLOOKUP(N10,'Wet-Dry Months'!$F$3:$G$541,2,FALSE) -> 2016
C11: ='Wet-Dry Months'!AG11 -> 130 | D11: ='Wet-Dry Months'!AH11 -> 147 | E11: =$C$1&'Wet-Dry Months'!AI11 -> 'Wet-Dry Months'!F130:F147 | F11: 8 | G11: =AVERAGEIFS('Wet-Dry Months'!$F$4:$F$541,'Wet-Dry Months'!$I$4:$I$541,'Final Grids'!G$3,'Wet-Dry Months'!$D$4:$D$541,'Final Grids'!$F11) -> 274.41471 | H11: =AVERAGEIFS('Wet-Dry Months'!$F$4:$F$541,'Wet-Dry Months'!$I$4:$I$541,'Final Grids'!H$3,'Wet-Dry Months'!$D$4:$D$541,'Final Grids'!$F11) -> 155.2677 | I11: =AVERAGEIFS('Wet-Dry Months'!$F$4:$F$541,'Wet-Dry Months'!$I$4:$I$541,'Final Grids'!I$3,'Wet-Dry Months'!$D$4:$D$541,'Final Grids'!$F11) -> 87.672588 | K11: 8 | L11: =IF(L49<L81,L33,L65) -> 271.99775 | M11: =IF(M49<M81,M33,M65) -> 148.29094 | N11: =IF(N49<N81,N33,N65) -> 96.682842 | P11: 8 | Q11: =VLOOKUP(L11,'Wet-Dry Months'!$F$3:$G$541,2,FALSE) -> 2022 | R11: =VLOOKUP(M11,'Wet-Dry Months'!$F$3:$G$541,2,FALSE) -> 2018 | S11: =VLOOKUP(N11,'Wet-Dry Months'!$F$3:$G$541,2,FALSE) -> 2015
C12: ='Wet-Dry Months'!AG12 -> 148 | D12: ='Wet-Dry Months'!AH12 -> 165 | E12: =$C$1&'Wet-Dry Months'!AI12 -> 'Wet-Dry Months'!F148:F165 | F12: 9 | G12: =AVERAGEIFS('Wet-Dry Months'!$F$4:$F$541,'Wet-Dry Months'!$I$4:$I$541,'Final Grids'!G$3,'Wet-Dry Months'!$D$4:$D$541,'Final Grids'!$F12) -> 212.53751 | H12: =AVERAGEIFS('Wet-Dry Months'!$F$4:$F$541,'Wet-Dry Months'!$I$4:$I$541,'Final Grids'!H$3,'Wet-Dry Months'!$D$4:$D$541,'Final Grids'!$F12) -> 117.10082 | I12: =AVERAGEIFS('Wet-Dry Months'!$F$4:$F$541,'Wet-Dry Months'!$I$4:$I$541,'Final Grids'!I$3,'Wet-Dry Months'!$D$4:$D$541,'Final Grids'!$F12) -> 63.743447 | K12: 9 | L12: =IF(L50<L82,L34,L66) -> 205.85764 | M12: =IF(M50<M82,M34,M66) -> 113.14663 | N12: =IF(N50<N82,N34,N66) -> 63.935121 | P12: 9 | Q12: =VLOOKUP(L12,'Wet-Dry Months'!$F$3:$G$541,2,FALSE) -> 2008 | R12: =VLOOKUP(M12,'Wet-Dry Months'!$F$3:$G$541,2,FALSE) -> 2014 | S12: =VLOOKUP(N12,'Wet-Dry Months'!$F$3:$G$541,2,FALSE) -> 2022
C13: ='Wet-Dry Months'!AG13 -> 166 | D13: ='Wet-Dry Months'!AH13 -> 183 | E13: =$C$1&'Wet-Dry Months'!AI13 -> 'Wet-Dry Months'!F166:F183 | F13: 10 | G13: =AVERAGEIFS('Wet-Dry Months'!$F$4:$F$541,'Wet-Dry Months'!$I$4:$I$541,'Final Grids'!G$3,'Wet-Dry Months'!$D$4:$D$541,'Final Grids'!$F13) -> 191.55789 | H13: =AVERAGEIFS('Wet-Dry Months'!$F$4:$F$541,'Wet-Dry Months'!$I$4:$I$541,'Final Grids'!H$3,'Wet-Dry Months'!$D$4:$D$541,'Final Grids'!$F13) -> 91.207557 | I13: =AVERAGEIFS('Wet-Dry Months'!$F$4:$F$541,'Wet-Dry Months'!$I$4:$I$541,'Final Grids'!I$3,'Wet-Dry Months'!$D$4:$D$541,'Final Grids'!$F13) -> 28.475235 | K13: 10 | L13: =IF(L51<L83,L35,L67) -> 193.88713 | M13: =IF(M51<M83,M35,M67) -> 84.344507 | N13: =IF(N51<N83,N35,N67) -> 35.554346 | P13: 10 | Q13: =VLOOKUP(L13,'Wet-Dry Months'!$F$3:$G$541,2,FALSE) -> 2015 | R13: =VLOOKUP(M13,'Wet-Dry Months'!$F$3:$G$541,2,FALSE) -> 2021 | S13: =VLOOKUP(N13,'Wet-Dry Months'!$F$3:$G$541,2,FALSE) -> 2010
C14: ='Wet-Dry Months'!AG14 -> 184 | D14: ='Wet-Dry Months'!AH14 -> 201 | E14: =$C$1&'Wet-Dry Months'!AI14 -> 'Wet-Dry Months'!F184:F201 | F14: 11 | G14: =AVERAGEIFS('Wet-Dry Months'!$F$4:$F$541,'Wet-Dry Months'!$I$4:$I$541,'Final Grids'!G$3,'Wet-Dry Months'!$D$4:$D$541,'Final Grids'!$F14) -> 134.88239 | H14: =AVERAGEIFS('Wet-Dry Months'!$F$4:$F$541,'Wet-Dry Months'!$I$4:$I$541,'Final Grids'!H$3,'Wet-Dry Months'!$D$4:$D$541,'Final Grids'!$F14) -> 69.991235 | I14: =AVERAGEIFS('Wet-Dry Months'!$F$4:$F$541,'Wet-Dry Months'!$I$4:$I$541,'Final Grids'!I$3,'Wet-Dry Months'!$D$4:$D$541,'Final Grids'!$F14) -> 34.394429 | K14: 11 | L14: =IF(L52<L84,L36,L68) -> 128.90126 | M14: =IF(M52<M84,M36,M68) -> 70.123217 | N14: =IF(N52<N84,N36,N68) -> 35.951627 | P14: 11 | Q14: =VLOOKUP(L14,'Wet-Dry Months'!$F$3:$G$541,2,FALSE) -> 2010 | R14: =VLOOKUP(M14,'Wet-Dry Months'!$F$3:$G$541,2,FALSE) -> 2008 | S14: =VLOOKUP(N14,'Wet-Dry Months'!$F$3:$G$541,2,FALSE) -> 2012
C15: ='Wet-Dry Months'!AG15 -> 202 | D15: ='Wet-Dry Months'!AH15 -> 219 | E15: =$C$1&'Wet-Dry Months'!AI15 -> 'Wet-Dry Months'!F202:F219 | F15: 12 | G15: =AVERAGEIFS('Wet-Dry Months'!$F$4:$F$541,'Wet-Dry Months'!$I$4:$I$541,'Final Grids'!G$3,'Wet-Dry Months'!$D$4:$D$541,'Final Grids'!$F15) -> 191.24499 | H15: =AVERAGEIFS('Wet-Dry Months'!$F$4:$F$541,'Wet-Dry Months'!$I$4:$I$541,'Final Grids'!H$3,'Wet-Dry Months'!$D$4:$D$541,'Final Grids'!$F15) -> 112.7116 | I15: =AVERAGEIFS('Wet-Dry Months'!$F$4:$F$541,'Wet-Dry Months'!$I$4:$I$541,'Final Grids'!I$3,'Wet-Dry Months'!$D$4:$D$541,'Final Grids'!$F15) -> 76.775554 | K15: 12 | L15: =IF(L53<L85,L37,L69) -> 183.04649 | M15: =IF(M53<M85,M37,M69) -> 116.28625 | N15: =IF(N53<N85,N37,N69) -> 72.129332 | P15: 12 | Q15: =VLOOKUP(L15,'Wet-Dry Months'!$F$3:$G$541,2,FALSE) -> 2006 | R15: =VLOOKUP(M15,'Wet-Dry Months'!$F$3:$G$541,2,FALSE) -> 2014 | S15: =VLOOKUP(N15,'Wet-Dry Months'!$F$3:$G$541,2,FALSE) -> 2011
K17: Finding the monthly WDA values just above and just below the long-term average (i.e. climate normals for the AORC dataset over the coastal zone region). Then, calculate a departure from normal (DFN) to assess which value is closest and thus represents the most average of each of the three conditions.
K24: Value just below avg conditions …
K25: Month | L25: Wet | M25: Avg | N25: Dry
K26: 1 | L26: {=INDIRECT($C$1&$E$1&$C4-1+_xlfn.XMATCH(G4,INDIRECT($E4),-1))} -> 145.71685 | M26: {=INDIRECT($C$1&$E$1&$C4-1+_xlfn.XMATCH(H4,INDIRECT($E4),-1))} -> 105.13069 | N26: {=INDIRECT($C$1&$E$1&$C4-1+_xlfn.XMATCH(I4,INDIRECT($E4),-1))} -> 63.552695
K27: 2 | L27: {=INDIRECT($C$1&$E$1&$C5-1+_xlfn.XMATCH(G5,INDIRECT($E5),-1))} -> 150.48279 | M27: {=INDIRECT($C$1&$E$1&$C5-1+_xlfn.XMATCH(H5,INDIRECT($E5),-1))} -> 90.962623 | N27: {=INDIRECT($C$1&$E$1&$C5-1+_xlfn.XMATCH(I5,INDIRECT($E5),-1))} -> 52.845072
K28: 3 | L28: {=INDIRECT($C$1&$E$1&$C6-1+_xlfn.XMATCH(G6,INDIRECT($E6),-1))} -> 144.5698 | M28: {=INDIRECT($C$1&$E$1&$C6-1+_xlfn.XMATCH(H6,INDIRECT($E6),-1))} -> 97.170449 | N28: {=INDIRECT($C$1&$E$1&$C6-1+_xlfn.XMATCH(I6,INDIRECT($E6),-1))} -> 46.289565
K29: 4 | L29: {=INDIRECT($C$1&$E$1&$C7-1+_xlfn.XMATCH(G7,INDIRECT($E7),-1))} -> 180.30434 | M29: {=INDIRECT($C$1&$E$1&$C7-1+_xlfn.XMATCH(H7,INDIRECT($E7),-1))} -> 114.01293 | N29: {=INDIRECT($C$1&$E$1&$C7-1+_xlfn.XMATCH(I7,INDIRECT($E7),-1))} -> 32.604745
K30: 5 | L30: {=INDIRECT($C$1&$E$1&$C8-1+_xlfn.XMATCH(G8,INDIRECT($E8),-1))} -> 193.09739 | M30: {=INDIRECT($C$1&$E$1&$C8-1+_xlfn.XMATCH(H8,INDIRECT($E8),-1))} -> 137.19522 | N30: {=INDIRECT($C$1&$E$1&$C8-1+_xlfn.XMATCH(I8,INDIRECT($E8),-1))} -> 67.343949
K31: 6 | L31: {=INDIRECT($C$1&$E$1&$C9-1+_xlfn.XMATCH(G9,INDIRECT($E9),-1))} -> 192.05579 | M31: {=INDIRECT($C$1&$E$1&$C9-1+_xlfn.XMATCH(H9,INDIRECT($E9),-1))} -> 132.55115 | N31: {=INDIRECT($C$1&$E$1&$C9-1+_xlfn.XMATCH(I9,INDIRECT($E9),-1))} -> 84.480906
K32: 7 | L32: {=INDIRECT($C$1&$E$1&$C10-1+_xlfn.XMATCH(G10,INDIRECT($E10),-1))} -> 216.73227 | M32: {=INDIRECT($C$1&$E$1&$C10-1+_xlfn.XMATCH(H10,INDIRECT($E10),-1))} -> 168.92453 | N32: {=INDIRECT($C$1&$E$1&$C10-1+_xlfn.XMATCH(I10,INDIRECT($E10),-1))} -> 106.49716
K33: 8 | L33: {=INDIRECT($C$1&$E$1&$C11-1+_xlfn.XMATCH(G11,INDIRECT($E11),-1))} -> 271.99775 | M33: {=INDIRECT($C$1&$E$1&$C11-1+_xlfn.XMATCH(H11,INDIRECT($E11),-1))} -> 148.29094 | N33: {=INDIRECT($C$1&$E$1&$C11-1+_xlfn.XMATCH(I11,INDIRECT($E11),-1))} -> 54.42588
K34: 9 | L34: {=INDIRECT($C$1&$E$1&$C12-1+_xlfn.XMATCH(G12,INDIRECT($E12),-1))} -> 205.85764 | M34: {=INDIRECT($C$1&$E$1&$C12-1+_xlfn.XMATCH(H12,INDIRECT($E12),-1))} -> 113.14663 | N34: {=INDIRECT($C$1&$E$1&$C12-1+_xlfn.XMATCH(I12,INDIRECT($E12),-1))} -> 49.027695
K35: 10 | L35: {=INDIRECT($C$1&$E$1&$C13-1+_xlfn.XMATCH(G13,INDIRECT($E13),-1))} -> 149.24153 | M35: {=INDIRECT($C$1&$E$1&$C13-1+_xlfn.XMATCH(H13,INDIRECT($E13),-1))} -> 84.344507 | N35: {=INDIRECT($C$1&$E$1&$C13-1+_xlfn.XMATCH(I13,INDIRECT($E13),-1))} -> 18.10124
K36: 11 | L36: {=INDIRECT($C$1&$E$1&$C14-1+_xlfn.XMATCH(G14,INDIRECT($E14),-1))} -> 128.90126 | M36: {=INDIRECT($C$1&$E$1&$C14-1+_xlfn.XMATCH(H14,INDIRECT($E14),-1))} -> 68.556446 | N36: {=INDIRECT($C$1&$E$1&$C14-1+_xlfn.XMATCH(I14,INDIRECT($E14),-1))} -> 27.182445
K37: 12 | L37: {=INDIRECT($C$1&$E$1&$C15-1+_xlfn.XMATCH(G15,INDIRECT($E15),-1))} -> 183.04649 | M37: {=INDIRECT($C$1&$E$1&$C15-1+_xlfn.XMATCH(H15,INDIRECT($E15),-1))} -> 108.67331 | N37: {=INDIRECT($C$1&$E$1&$C15-1+_xlfn.XMATCH(I15,INDIRECT($E15),-1))} -> 72.129332
K40: Value just below avg conditions … (DFN)
K41: Month | L41: Wet | M41: Avg | N41: Dry
K42: 1 | L42: =G4-L26 -> 15.924465 | M42: =H4-M26 -> 1.044202 | N42: =I4-N26 -> 5.0748731
K43: 2 | L43: =G5-L27 -> 5.2466993 | M43: =H5-M27 -> 2.7238895 | N43: =I5-N27 -> 7.8154863
K44: 3 | L44: =G6-L28 -> 20.884052 | M44: =H6-M28 -> 3.1106331 | N44: =I6-N28 -> 3.6933063
K45: 4 | L45: =G7-L29 -> 9.8939385 | M45: =H7-M29 -> 2.2329261 | N45: =I7-N29 -> 30.025287
K46: 5 | L46: =G8-L30 -> 10.77538 | M46: =H8-M30 -> 4.0910701 | N46: =I8-N30 -> 14.045758
K47: 6 | L47: =G9-L31 -> 8.2879762 | M47: =H9-M31 -> 0.27289041 | N47: =I9-N31 -> 3.5620761
K48: 7 | L48: =G10-L32 -> 0.1762389 | M48: =H10-M32 -> 5.1027616 | N48: =I10-N32 -> 12.682139
K49: 8 | L49: =G11-L33 -> 2.4169615 | M49: =H11-M33 -> 6.9767523 | N49: =I11-N33 -> 33.246708
...
