Workbook

Sheet area_comparison
A1: ICM_ID | B1: new_area_m2 | C1: old_area_m2 | D1: new-old | E1: old_comp_to_use_for_new_rain
A2: 1 | B2: =_xlfn.XLOOKUP(A2,new!C:C,new!BF:BF) -> 103699000 | C2: =_xlfn.XLOOKUP(A2,old!C:C,old!AP:AP) -> 89414000 | D2: =B2-C2 -> 14285000 | E2: =A2 -> 1
A3: 2 | B3: =_xlfn.XLOOKUP(A3,new!C:C,new!BF:BF) -> 73299200 | C3: =_xlfn.XLOOKUP(A3,old!C:C,old!AP:AP) -> 73299200 | D3: =B3-C3 -> 0 | E3: =A3 -> 2
A4: 3 | B4: =_xlfn.XLOOKUP(A4,new!C:C,new!BF:BF) -> 19385800 | C4: =_xlfn.XLOOKUP(A4,old!C:C,old!AP:AP) -> 19385800 | D4: =B4-C4 -> 0 | E4: =A4 -> 3
A5: 4 | B5: =_xlfn.XLOOKUP(A5,new!C:C,new!BF:BF) -> 20564600 | C5: =_xlfn.XLOOKUP(A5,old!C:C,old!AP:AP) -> 20564600 | D5: =B5-C5 -> 0 | E5: =A5 -> 4
A6: 5 | B6: =_xlfn.XLOOKUP(A6,new!C:C,new!BF:BF) -> 13723600 | C6: =_xlfn.XLOOKUP(A6,old!C:C,old!AP:AP) -> 24064800 | D6: =B6-C6 -> -10341200 | E6: =A6 -> 5
A7: 6 | B7: =_xlfn.XLOOKUP(A7,new!C:C,new!BF:BF) -> 37491900 | C7: =_xlfn.XLOOKUP(A7,old!C:C,old!AP:AP) -> 37491900 | D7: =B7-C7 -> 0 | E7: =A7 -> 6
A8: 7 | B8: =_xlfn.XLOOKUP(A8,new!C:C,new!BF:BF) -> 16365900 | C8: =_xlfn.XLOOKUP(A8,old!C:C,old!AP:AP) -> 14809700 | D8: =B8-C8 -> 1556200 | E8: =A8 -> 7
A9: 8 | B9: =_xlfn.XLOOKUP(A9,new!C:C,new!BF:BF) -> 21156500 | C9: =_xlfn.XLOOKUP(A9,old!C:C,old!AP:AP) -> 13390600 | D9: =B9-C9 -> 7765900 | E9: =A9 -> 8
A10: 9 | B10: =_xlfn.XLOOKUP(A10,new!C:C,new!BF:BF) -> 22013600 | C10: =_xlfn.XLOOKUP(A10,old!C:C,old!AP:AP) -> 21659000 | D10: =B10-C10 -> 354600 | E10: =A10 -> 9
A11: 10 | B11: =_xlfn.XLOOKUP(A11,new!C:C,new!BF:BF) -> 24574500 | C11: =_xlfn.XLOOKUP(A11,old!C:C,old!AP:AP) -> 24574500 | D11: =B11-C11 -> 0 | E11: =A11 -> 10
A12: 11 | B12: =_xlfn.XLOOKUP(A12,new!C:C,new!BF:BF) -> 28239000 | C12: =_xlfn.XLOOKUP(A12,old!C:C,old!AP:AP) -> 28239000 | D12: =B12-C12 -> 0 | E12: =A12 -> 11
A13: 12 | B13: =_xlfn.XLOOKUP(A13,new!C:C,new!BF:BF) -> 30197800 | C13: =_xlfn.XLOOKUP(A13,old!C:C,old!AP:AP) -> 30197800 | D13: =B13-C13 -> 0 | E13: =A13 -> 12
... A1000: 999 | B1000: =_xlfn.XLOOKUP(A1000,new!C:C,new!BF:BF) -> 3080720 | C1000: =_xlfn.XLOOKUP(A1000,old!C:C,old!AP:AP) -> 3080720 | D1000: =B1000-C1000 -> 0 | E1000: =A1000 -> 999
A1001: 1000 | B1001: =_xlfn.XLOOKUP(A1001,new!C:C,new!BF:BF) -> 5987210 | C1001: =_xlfn.XLOOKUP(A1001,old!C:C,old!AP:AP) -> 2653110 | D1001: =B1001-C1001 -> 3334100 | E1001: 1471
A1002: 1001 | B1002: =_xlfn.XLOOKUP(A1002,new!C:C,new!BF:BF) -> 7365320 | C1002: =_xlfn.XLOOKUP(A1002,old!C:C,old!AP:AP) -> 7365320 | D1002: =B1002-C1002 -> 0 | E1002: =A1002 -> 1001
A1003: 1002 | B1003: =_xlfn.XLOOKUP(A1003,new!C:C,new!BF:BF) -> 4109630 | C1003: =_xlfn.XLOOKUP(A1003,old!C:C,old!AP:AP) -> 4109630 | D1003: =B1003-C1003 -> 0 | E1003: =A1003 -> 1002
A1004: 1003 | B1004: =_xlfn.XLOOKUP(A1004,new!C:C,new!BF:BF) -> 3966320 | C1004: =_xlfn.XLOOKUP(A1004,old!C:C,old!AP:AP) -> 3966320 | D1004: =B1004-C1004 -> 0 | E1004: =A1004 -> 1003
A1005: 1004 | B1005: =_xlfn.XLOOKUP(A1005,new!C:C,new!BF:BF) -> 4524110 | C1005: =_xlfn.XLOOKUP(A1005,old!C:C,old!AP:AP) -> 4524110 | D1005: =B1005-C1005 -> 0 | E1005: =A1005 -> 1004
A1006: 1005 | B1006: =_xlfn.XLOOKUP(A1006,new!C:C,new!BF:BF) -> 2609320 | C1006: =_xlfn.XLOOKUP(A1006,old!C:C,old!AP:AP) -> 2609320 | D1006: =B1006-C1006 -> 0 | E1006: =A1006 -> 1005
A1007: 1006 | B1007: =_xlfn.XLOOKUP(A1007,new!C:C,new!BF:BF) -> 6578360 | C1007: =_xlfn.XLOOKUP(A1007,old!C:C,old!AP:AP) -> 6578360 | D1007: =B1007-C1007 -> 0 | E1007: =A1007 -> 1006
A1008: 1007 | B1008: =_xlfn.XLOOKUP(A1008,new!C:C,new!BF:BF) -> 21108600 | C1008: =_xlfn.XLOOKUP(A1008,old!C:C,old!AP:AP) -> 21108600 | D1008: =B1008-C1008 -> 0 | E1008: =A1008 -> 1007
A1009: 1008 | B1009: =_xlfn.XLOOKUP(A1009,new!C:C,new!BF:BF) -> 10087100 | C1009: =_xlfn.XLOOKUP(A1009,old!C:C,old!AP:AP) -> 10087100 | D1009: =B1009-C1009 -> 0 | E1009: =A1009 -> 1008
A1010: 1009 | B1010: =_xlfn.XLOOKUP(A1010,new!C:C,new!BF:BF) -> 2389270 | C1010: =_xlfn.XLOOKUP(A1010,old!C:C,old!AP:AP) -> 2389270 | D1010: =B1010-C1010 -> 0 | E1010: =A1010 -> 1009
A1011: 1010 | B1011: =_xlfn.XLOOKUP(A1011,new!C:C,new!BF:BF) -> 4481010 | C1011: =_xlfn.XLOOKUP(A1011,old!C:C,old!AP:AP) -> 4481010 | D1011: =B1011-C1011 -> 0 | E1011: =A1011 -> 1010
A1012: 1011 | B1012: =_xlfn.XLOOKUP(A1012,new!C:C,new!BF:BF) -> 6639190 | C1012: =_xlfn.XLOOKUP(A1012,old!C:C,old!AP:AP) -> 944311 | D1012: =B1012-C1012 -> 5694879 | E1012: 1136
A1013: 1012 | B1013: =_xlfn.XLOOKUP(A1013,new!C:C,new!BF:BF) -> 5483840 | C1013: =_xlfn.XLOOKUP(A1013,old!C:C,old!AP:AP) -> 1498830 | D1013: =B1013-C1013 -> 3985010 | E1013: =A1013 -> 1012
A1014: 1013 | B1014: =_xlfn.XLOOKUP(A1014,new!C:C,new!BF:BF) -> 31005400 | C1014: =_xlfn.XLOOKUP(A1014,old!C:C,old!AP:AP) -> 2404660 | D1014: =B1014-C1014 -> 28600740 | E1014: 1360
A1015: 1014 | B1015: =_xlfn.XLOOKUP(A1015,new!C:C,new!BF:BF) -> 8725700 | C1015: =_xlfn.XLOOKUP(A1015,old!C:C,old!AP:AP) -> 5988280 | D1015: =B1015-C1015 -> 2737420 | E1015: 1360
A1016: 1015 | B1016: =_xlfn.XLOOKUP(A1016,new!C:C,new!BF:BF) -> 10036800 | C1016: =_xlfn.XLOOKUP(A1016,old!C:C,old!AP:AP) -> 4819120 | D1016: =B1016-C1016 -> 5217680 | E1016: =A1016 -> 1015
A1017: 1016 | B1017: =_xlfn.XLOOKUP(A1017,new!C:C,new!BF:BF) -> 9429930 | C1017: =_xlfn.XLOOKUP(A1017,old!C:C,old!AP:AP) -> 2359070 | D1017: =B1017-C1017 -> 7070860 | E1017: =A1017 -> 1016
A1018: 1017 | B1018: =_xlfn.XLOOKUP(A1018,new!C:C,new!BF:BF) -> 3223320 | C1018: =_xlfn.XLOOKUP(A1018,old!C:C,old!AP:AP) -> 1212500 | D1018: =B1018-C1018 -> 2010820 | E1018: 1360
A1019: 1018 | B1019: =_xlfn.XLOOKUP(A1019,new!C:C,new!BF:BF) -> 2174890 | C1019: =_xlfn.XLOOKUP(A1019,old!C:C,old!AP:AP) -> 2174890 | D1019: =B1019-C1019 -> 0 | E1019: =A1019 -> 1018
A1020: 1019 | B1020: =_xlfn.XLOOKUP(A1020,new!C:C,new!BF:BF) -> 2505590 | C1020: =_xlfn.XLOOKUP(A1020,old!C:C,old!AP:AP) -> 2011620 | D1020: =B1020-C1020 -> 493970 | E1020: 1321
A1021: 1020 | B1021: =_xlfn.XLOOKUP(A1021,new!C:C,new!BF:BF) -> 61298400 | C1021: =_xlfn.XLOOKUP(A1021,old!C:C,old!AP:AP) -> 61298400 | D1021: =B1021-C1021 -> 0 | E1021: 1020
A1022: 1021 | B1022: =_xlfn.XLOOKUP(A1022,new!C:C,new!BF:BF) -> 912903 | C1022: =_xlfn.XLOOKUP(A1022,old!C:C,old!AP:AP) -> 1487750 | D1022: =B1022-C1022 -> -574847 | E1022: 1321
A1023: 1022 | B1023: =_xlfn.XLOOKUP(A1023,new!C:C,new!BF:BF) -> 2597050 | C1023: =_xlfn.XLOOKUP(A1023,old!C:C,old!AP:AP) -> 2597050 | D1023: =B1023-C1023 -> 0 | E1023: =A1023 -> 1022
A1024: 1023 | B1024: =_xlfn.XLOOKUP(A1024,new!C:C,new!BF:BF) -> 2095890 | C1024: =_xlfn.XLOOKUP(A1024,old!C:C,old!AP:AP) -> 2095890 | D1024: =B1024-C1024 -> 0 | E1024: =A1024 -> 1023
A1025: 1024 | B1025: =_xlfn.XLOOKUP(A1025,new!C:C,new!BF:BF) -> 4997660 | C1025: =_xlfn.XLOOKUP(A1025,old!C:C,old!AP:AP) -> 4997660 | D1025: =B1025-C1025 -> 0 | E1025: =A1025 -> 1024
A1026: 1025 | B1026: =_xlfn.XLOOKUP(A1026,new!C:C,new!BF:BF) -> 16323300 | C1026: =_xlfn.XLOOKUP(A1026,old!C:C,old!AP:AP) -> 16323300 | D1026: =B1026-C1026 -> 0 | E1026: =A1026 -> 1025
...

Sheet old
A1: attribute table from: Cells_Coastwide_upland_MP29Task23_v4_noVoid
A2: FID | B2: Shape * | C2: ICM_ID | D2: TotalArea | E2: PercWater | F2: PercUpland | G2: PercMarsh | H2: MarshEdgeA | I2: WSEL_ini | J2: bed_elev | K2: ero_bed_dp | L2: percETcalc | M2: init_sal | N2: RainGage | O2: WindGage | P2: ETGage | Q2: CurCoeff | R2: bedFricCoe | S2: NonSandExp | T2: NonSandCoe | U2: SandCoeff | V2: KadlacKa | W2: KadlacKdep | X2: MEErosion | Y2: marsh_elev | Z2: soil_moi_d | AA2: SedDepo_f | AB2: Eh_adj | AC2: marsh_ELsd | AD2: Notes | AE2: ICM_region | AF2: LW_update | AG2: Projectnam | AH2: Bulk_dens | AI2: offshorTSS | AJ2: TideGage | AK2: sand_adapt | AL2: Tributary | AM2: Trib_Num | AN2: Qmult | AO2: CRMS_stnid | AP2: area_m2
A3: 0 | B3: Polygon ZM | C3: 1 | D3: 89413998 | E3: 0.025921 | F3: 0.639069 | G3: 0.33501 | H3: 349300 | I3: 0 | J3: -0.00385 | K3: 0.05 | L3: 10 | M3: 0 | N3: 286 | O3: 196 | P3: 1 | Q3: 0.023 | R3: 0.001 | S3: 1 | T3: 0 | U3: 0.008 | V3: 0.05 | W3: 0.05 | X3: 0 | Y3: 3.927539 | Z3: 0.2 | AA3: 1 | AB3: -7.257101 | AC3: 7.257101 | AD3: 2D compartment | AE3: PB | AF3: 1 | AH3: 0.835 | AI3: -9999 | AK3: 0.25 | AP3: 89414000
A4: 1 | B4: Polygon ZM | C4: 2 | D4: 73299177 | E4: 0.001277 | F4: 0.032074 | G4: 0.966649 | H4: 42800 | I4: 0 | J4: -0.502225 | K4: 0.05 | L4: 10 | M4: 0 | N4: 286 | O4: 197 | P4: 1 | Q4: 0.023 | R4: 0.001 | S4: 1 | T4: 0 | U4: 0.008 | V4: 0.05 | W4: 0.05 | X4: 0 | Y4: 0.481542 | Z4: 0.2 | AA4: 1 | AB4: -1.556331 | AC4: 1.556331 | AD4: 2D compartment | AE4: PB | AF4: 1 | AH4: 0.835 | AI4: -9999 | AK4: 0.25 | AO4: CRMS0065-H02 | AP4: 73299200
A5: 2 | B5: Polygon ZM | C5: 3 | D5: 19385799 | E5: 0.00147 | F5: 0.037538 | G5: 0.960992 | H5: 88500 | I5: 0 | J5: -0.5 | K5: 0.05 | L5: 10 | M5: 0 | N5: 286 | O5: 197 | P5: 1 | Q5: 0.023 | R5: 0.001 | S5: 1 | T5: 0 | U5: 0.008 | V5: 0.05 | W5: 0.05 | X5: 0 | Y5: 0.251051 | Z5: 0.2 | AA5: 1 | AB5: -0.16967 | AC5: 0.16967 | AD5: 2D compartment | AE5: PB | AF5: 1 | AG5: West Maurepas Swamp | AH5: 0.835 | AI5: -9999 | AK5: 0.25 | AO5: CRMS5167-H01 | AP5: 19385800
A6: 3 | B6: Polygon ZM | C6: 4 | D6: 20564566 | E6: 0.000754 | F6: 0.021873 | G6: 0.977374 | H6: 69200 | I6: 0 | J6: -0.5 | K6: 0.05 | L6: 10 | M6: 0 | N6: 286 | O6: 210 | P6: 1 | Q6: 0.023 | R6: 0.001 | S6: 1 | T6: 0 | U6: 0.008 | V6: 0.05 | W6: 0.05 | X6: 0 | Y6: 0.338133 | Z6: 0.2 | AA6: 1 | AB6: -0.20836 | AC6: 0.20836 | AD6: 2D compartment | AE6: PB | AF6: 1 | AH6: 0.835 | AI6: -9999 | AK6: 0.25 | AO6: CRMS0039-H01 | AP6: 20564600
A7: 4 | B7: Polygon ZM | C7: 5 | D7: 24064804 | E7: 0.001554 | F7: 0.126492 | G7: 0.871954 | H7: 18000 | I7: 0 | J7: -0.664898 | K7: 0.05 | L7: 10 | M7: 0 | N7: 261 | O7: 210 | P7: 1 | Q7: 0.023 | R7: 0.001 | S7: 1 | T7: 0 | U7: 0.008 | V7: 0.05 | W7: 0.05 | X7: 0 | Y7: 0.398635 | Z7: 0.2 | AA7: 1 | AB7: -0.241379 | AC7: 0.241379 | AD7: 2D compartment | AE7: PB | AF7: 1 | AH7: 0.835 | AI7: -9999 | AK7: 0.25 | AP7: 24064800
A8: 5 | B8: Polygon ZM | C8: 6 | D8: 37491882 | E8: 0.055855 | F8: 0.700672 | G8: 0.243474 | H8: 339700 | I8: 0 | J8: -0.00385 | K8: 0.05 | L8: 10 | M8: 0 | N8: 261 | O8: 209 | P8: 1 | Q8: 0.023 | R8: 0.001 | S8: 1 | T8: 0 | U8: 0.008 | V8: 0.05 | W8: 0.05 | X8: 0 | Y8: 3.109962 | Z8: 0.2 | AA8: 1 | AB8: -2.760475 | AC8: 2.760475 | AD8: 2D compartment | AE8: PB | AF8: 1 | AH8: 0.835 | AI8: -9999 | AK8: 0.25 | AP8: 37491900
A9: 6 | B9: Polygon ZM | C9: 7 | D9: 14809665 | E9: 0.001654 | F9: 0.286833 | G9: 0.711513 | H9: 33000 | I9: 0 | J9: -0.219645 | K9: 0.05 | L9: 10 | M9: 0 | N9: 261 | O9: 223 | P9: 1 | Q9: 0.023 | R9: 0.001 | S9: 1 | T9: 0 | U9: 0.008 | V9: 0.05 | W9: 0.05 | X9: 0 | Y9: 0.434669 | Z9: 0.2 | AA9: 1 | AB9: -0.273317 | AC9: 0.273317 | AD9: 2D compartment | AE9: PB | AF9: 1 | AH9: 0.835 | AI9: -9999 | AK9: 0.25 | AO9: CRMS0059-H02 | AP9: 14809700
A10: 7 | B10: Polygon ZM | C10: 8 | D10: 13390575 | E10: 0.012225 | F10: 0.844325 | G10: 0.14345 | H10: 24300 | I10: 0 | J10: -0.00385 | K10: 0.05 | L10: 10 | M10: 0 | N10: 261 | O10: 223 | P10: 1 | Q10: 0.023 | R10: 0.001 | S10: 1 | T10: 0 | U10: 0.008 | V10: 0.05 | W10: 0.05 | X10: 0 | Y10: 1.048059 | Z10: 0.2 | AA10: 1 | AB10: -0.550358 | AC10: 0.550358 | AD10: 2D compartment | AE10: PB | AF10: 1 | AH10: 0.835 | AI10: -9999 | AK10: 0.25 | AP10: 13390600
A11: 8 | B11: Polygon ZM | C11: 9 | D11: 21659036 | E11: 0.000891 | F11: 0.343926 | G11: 0.655183 | H11: 31200 | I11: 0 | J11: -0.006528 | K11: 0.05 | L11: 10 | M11: 0 | N11: 261 | O11: 223 | P11: 1 | Q11: 0.023 | R11: 0.001 | S11: 1 | T11: 0 | U11: 0.008 | V11: 0.05 | W11: 0.05 | X11: 0.014247 | Y11: 0.751304 | Z11: 0.2 | AA11: 1 | AB11: -0.546379 | AC11: 0.546379 | AD11: 2D compartment | AE11: PB | AF11: 1 | AH11: 0.835 | AI11: -9999 | AK11: 0.25 | AP11: 21659000
A12: 9 | B12: Polygon ZM | C12: 10 | D12: 24574494 | E12: 0.011402 | F12: 0.747808 | G12: 0.24079 | H12: 68300 | I12: 0 | J12: -0.00385 | K12: 0.05 | L12: 10 | M12: 0 | N12: 261 | O12: 223 | P12: 1 | Q12: 0.023 | R12: 0.001 | S12: 1 | T12: 0 | U12: 0.008 | V12: 0.05 | W12: 0.05 | X12: 0 | Y12: 2.251615 | Z12: 0.2 | AA12: 1 | AB12: -1.00122 | AC12: 1.00122 | AD12: 2D compartment | AE12: PB | AF12: 1 | AH12: 0.835 | AI12: -9999 | AK12: 0.25 | AP12: 24574500
A13: 10 | B13: Polygon ZM | C13: 11 | D13: 28238972 | E13: 0.144839 | F13: 0.063586 | G13: 0.791575 | H13: 1800400 | I13: 0 | J13: -0.50882 | K13: 0.05 | L13: 10 | M13: 0 | N13: 230 | O13: 223 | P13: 1 | Q13: 0.023 | R13: 0.001 | S13: 1 | T13: 0 | U13: 0.008 | V13: 0.05 | W13: 0.05 | X13: 0.083592 | Y13: 0.857267 | Z13: 0.2 | AA13: 1 | AB13: -0.659619 | AC13: 0.659619 | AD13: 2D tributary boundary (Qmult > 0) | AE13: PB | AF13: 1 | AH13: 0.835 | AI13: -9999 | AK13: 0.25 | AL13: Bonnet Carre Spillway | AM13: 42 | AN13: 1 | AP13: 28239000
A14: 11 | B14: Polygon ZM | C14: 12 | D14: 30197797 | E14: 0.176784 | F14: 0.033668 | G14: 0.789548 | H14: 1178000 | I14: 0 | J14: -0.5859 | K14: 0.05 | L14: 10 | M14: 0 | N14: 209 | O14: 237 | P14: 1 | Q14: 0.023 | R14: 0.001 | S14: 1 | T14: 0 | U14: 0.008 | V14: 0.05 | W14: 0.05 | X14: 0.101319 | Y14: 0.226043 | Z14: 0.2 | AA14: 1 | AB14: -0.234327 | AC14: 0.234327 | AD14: 2D tributary boundary (Qmult > 0) | AE14: PB | AF14: 1 | AH14: 0.835 | AI14: -9999 | AK14: 0.25 | AL14: LaBranche Hydrologic Restoration | AM14: 44 | AN14: 1 | AP14: 30197800
A15: 12 | B15: Polygon ZM | C15: 13 | D15: 227355705 | E15: 0.007775 | F15: 0.978743 | G15: 0.013482 | H15: 348300 | I15: 0 | J15: -0.950618 | K15: 0.05 | L15: 10 | M15: 0 | N15: 106 | O15: 237 | P15: 1 | Q15: 0.023 | R15: 0.001 | S15: 1 | T15: 0 | U15: 0.008 | V15: 0.05 | W15: 0.05 | X15: 0.004667 | Y15: 0.117142 | Z15: 0.2 | AA15: 1 | AB15: -1.928741 | AC15: 1.928741 | AD15: 2D compartment | AE15: PB | AF15: 1 | AH15: 0.835 | AI15: -9999 | AK15: 0.25 | AP15: 227356000
A16: 13 | B16: Polygon ZM | C16: 14 | D16: 59310369 | E16: 0.01939 | F16: 0.846039 | G16: 0.134571 | H16: 235500 | I16: 0 | J16: -3.115465 | K16: 0.05 | L16: 10 | M16: 0 | N16: 63 | O16: 265 | P16: 1 | Q16: 0.023 | R16: 0.001 | S16: 1 | T16: 0 | U16: 0.008 | V16: 0.05 | W16: 0.05 | X16: 0.048285 | Y16: -0.631149 | Z16: 0.2 | AA16: 1 | AB16: -2.494045 | AC16: 2.494045 | AD16: 2D compartment | AE16: PB | AF16: 1 | AH16: 0.835 | AI16: -9999 | AK16: 0.25 | AP16: 59310400
A17: 14 | B17: Polygon ZM | C17: 15 | D17: 43748405 | E17: 0.012451 | F17: 0.011486 | G17: 0.976063 | H17: 417100 | I17: 0 | J17: -2.86 | K17: 0.05 | L17: 10 | M17: 0 | N17: 274 | O17: 197 | P17: 1 | Q17: 0.023 | R17: 0.001 | S17: 1 | T17: 0 | U17: 0.008 | V17: 0.05 | W17: 0.05 | X17: 0.077421 | Y17: 0.31917 | Z17: 0.2 | AA17: 1 | AB17: -0.192352 | AC17: 0.192352 | AD17: 2D tributary boundary (Qmult > 0) | AE17: PB | AF17: 1 | AG17: West Maurepas Swamp | AH17: 0.835 | AI17: -9999 | AK17: 0.25 | AL17: Union & West Maurepas Diversion | AM17: 38 + 39 | AN17: 1 + 1 | AP17: 43748400
A18: 15 | B18: Polygon ZM | C18: 16 | D18: 21927368 | E18: 0.000889 | F18: 0.007917 | G18: 0.991194 | H18: 91200 | I18: 0 | J18: -0.775204 | K18: 0.05 | L18: 10 | M18: 0 | N18: 236 | O18: 210 | P18: 1 | Q18: 0.023 | R18: 0.001 | S18: 1 | T18: 0 | U18: 0.008 | V18: 0.05 | W18: 0.05 | X18: 0 | Y18: 0.265363 | Z18: 0.2 | AA18: 1 | AB18: -0.116821 | AC18: 0.116821 | AD18: 2D tributary boundary (Qmult > 0) | AE18: PB | AF18: 1 | AG18: West Maurepas Swamp | AH18: 0.835 | AI18: -9999 | AK18: 0.25 | AL18: East Maurepas Diversion | AM18: 40 | AN18: 0.5 | AP18: 21927400
A19: 16 | B19: Polygon ZM | C19: 17 | D19: 21732064 | E19: 0.001109 | F19: 0.000115 | G19: 0.998776 | H19: 87800 | I19: 0 | J19: -2.494671 | K19: 0.05 | L19: 10 | M19: 0 | N19: 258 | O19: 210 | P19: 1 | Q19: 0.023 | R19: 0.001 | S19: 1 | T19: 0 | U19: 0.008 | V19: 0.05 | W19: 0.05 | X19: 0.039294 | Y19: 0.313757 | Z19: 0.2 | AA19: 1 | AB19: -0.120698 | AC19: 0.120698 | AD19: 2D compartment | AE19: PB | AF19: 1 | AG19: West Maurepas Swamp | AH19: 0.835 | AI19: -9999 | AK19: 0.25 | AO19: CRMS0097-H01 | AP19: 21732100
A20: 17 | B20: Polygon ZM | C20: 18 | D20: 30146863 | E20: 0.004465 | F20: 0.001038 | G20: 0.994497 | H20: 304100 | I20: 0 | J20: -0.95315 | K20: 0.05 | L20: 10 | M20: 0 | N20: 236 | O20: 210 | P20: 1 | Q20: 0.023 | R20: 0.001 | S20: 1 | T20: 0 | U20: 0.008 | V20: 0.05 | W20: 0.05 | X20: 0.091101 | Y20: 0.281152 | Z20: 0.2 | AA20: 1 | AB20: -0.129884 | AC20: 0.129884 | AD20: 2D compartment | AE20: PB | AF20: 1 | AG20: West Maurepas Swamp | AH20: 0.835 | AI20: -9999 | AK20: 0.25 | AO20: CRMS0061-H01 | AP20: 30146900
A21: 18 | B21: Polygon ZM | C21: 19 | D21: 25767723 | E21: 0.00012 | F21: 0.005189 | G21: 0.994691 | H21: 55500 | I21: 0 | J21: -0.5 | K21: 0.05 | L21: 10 | M21: 0 | N21: 236 | O21: 210 | P21: 1 | Q21: 0.023 | R21: 0.001 | S21: 1 | T21: 0 | U21: 0.008 | V21: 0.05 | W21: 0.05 | X21: 0 | Y21: 0.306674 | Z21: 0.2 | AA21: 1 | AB21: -0.114035 | AC21: 0.114035 | AD21: 2D tributary boundary (Qmult > 0) | AE21: PB | AF21: 1 | AG21: West Maurepas Swamp | AH21: 0.835 | AI21: -9999 | AK21: 0.25 | AL21: East Maurepas Diversion | AM21: 40 | AN21: 0.5 | AO21: CRMS5414-H01 | AP21: 25767700
A22: 19 | B22: Polygon ZM | C22: 20 | D22: 11803852 | E22: 0.000432 | F22: 0.000102 | G22: 0.999466 | H22: 61100 | I22: 0 | J22: -0.5 | K22: 0.05 | L22: 10 | M22: 0 | N22: 236 | O22: 210 | P22: 1 | Q22: 0.023 | R22: 0.001 | S22: 1 | T22: 0 | U22: 0.008 | V22: 0.05 | W22: 0.05 | X22: 0.070701 | Y22: 0.338019 | Z22: 0.2 | AA22: 1 | AB22: -0.079711 | AC22: 0.079711 | AD22: 2D compartment | AE22: PB | AF22: 1 | AG22: West Maurepas Swamp | AH22: 0.835 | AI22: -9999 | AK22: 0.25 | AP22: 11803900
A23: 20 | B23: Polygon ZM | C23: 21 | D23: 14083304 | E23: 0.000483 | F23: 0.002961 | G23: 0.996556 | H23: 25600 | I23: 0 | J23: -0.353891 | K23: 0.05 | L23: 10 | M23: 0 | N23: 236 | O23: 210 | P23: 1 | Q23: 0.023 | R23: 0.001 | S23: 1 | T23: 0 | U23: 0.008 | V23: 0.05 | W23: 0.05 | X23: 0 | Y23: 0.301171 | Z23: 0.2 | AA23: 1 | AB23: -0.106519 | AC23: 0.106519 | AD23: 2D compartment | AE23: PB | AF23: 1 | AH23: 0.835 | AI23: -9999 | AK23: 0.25 | AO23: CRMS0089-H02 | AP23: 14083300
A24: 21 | B24: Polygon ZM | C24: 22 | D24: 9098213 | E24: 0.001506 | F24: 0.008507 | G24: 0.989987 | H24: 32100 | I24: 0 | J24: -0.361492 | K24: 0.05 | L24: 10 | M24: 0 | N24: 236 | O24: 210 | P24: 1 | Q24: 0.023 | R24: 0.001 | S24: 1 | T24: 0 | U24: 0.008 | V24: 0.05 | W24: 0.05 | X24: 0.0332 | Y24: 0.340573 | Z24: 0.2 | AA24: 1 | AB24: -0.091441 | AC24: 0.091441 | AD24: 2D compartment | AE24: PB | AF24: 1 | AH24: 0.835 | AI24: -9999 | AK24: 0.25 | AO24: CRMS0090-W01 | AP24: 9098210
A25: 22 | B25: Polygon ZM | C25: 23 | D25: 17601074 | E25: 0.000795 | F25: 0.001347 | G25: 0.997858 | H25: 44000 | I25: 0 | J25: -0.288285 | K25: 0.05 | L25: 10 | M25: 0 | N25: 236 | O25: 224 | P25: 1 | Q25: 0.023 | R25: 0.001 | S25: 1 | T25: 0 | U25: 0.008 | V25: 0.05 | W25: 0.05 | X25: 0 | Y25: 0.356071 | Z25: 0.2 | AA25: 1 | AB25: -0.139808 | AC25: 0.139808 | AD25: 2D compartment | AE25: PB | AF25: 1 | AH25: 0.835 | AI25: -9999 | AK25: 0.25 | AO25: CRMS0047-H01 | AP25: 17601100
A26: 23 | B26: Polygon ZM | C26: 24 | D26: 13970240 | E26: 0.006442 | F26: 0 | G26: 0.993558 | H26: 109400 | I26: 0 | J26: -0.514421 | K26: 0.05 | L26: 10 | M26: 0 | N26: 136 | O26: 224 | P26: 1 | Q26: 0.023 | R26: 0.001 | S26: 1 | T26: 0 | U26: 0.008 | V26: 0.05 | W26: 0.05 | X26: 0.090165 | Y26: 0.328267 | Z26: 0.2 | AA26: 1 | AB26: -0.085418 | AC26: 0.085418 | AD26: 2D compartment | AE26: PB | AF26: 1 | AH26: 0.835 | AI26: -9999 | AK26: 0.25 | AO26: CRMS0058-H02 | AP26: 13970200
A27: 24 | B27: Polygon ZM | C27: 25 | D27: 23986679 | E27: 0.000233 | F27: 0.019286 | G27: 0.980481 | H27: 10200 | I27: 0 | J27: -0.376629 | K27: 0.05 | L27: 10 | M27: 0 | N27: 236 | O27: 224 | P27: 1 | Q27: 0.023 | R27: 0.001 | S27: 1 | T27: 0 | U27: 0.008 | V27: 0.05 | W27: 0.05 | X27: 0.000994 | Y27: 0.409305 | Z27: 0.2 | AA27: 1 | AB27: -0.105901 | AC27: 0.105901 | AD27: 2D compartment | AE27: PB | AF27: 1 | AH27: 0.835 | AI27: -9999 | AK27: 0.25 | AP27: 23986700
A28: 25 | B28: Polygon ZM | C28: 26 | D28: 20977096 | E28: 0.007508 | F28: 6.7e-05 | G28: 0.992425 | H28: 193600 | I28: 0 | J28: -0.5 | K28: 0.05 | L28: 10 | M28: 0 | N28: 136 | O28: 224 | P28: 1 | Q28: 0.023 | R28: 0.001 | S28: 1 | T28: 0 | U28: 0.008 | V28: 0.05 | W28: 0.05 | X28: 0.174654 | Y28: 0.287162 | Z28: 0.2 | AA28: 1 | AB28: -0.076718 | AC28: 0.076718 | AD28: 2D compartment | AE28: PB | AF28: 1 | AH28: 0.835 | AI28: -9999 | AK28: 0.25 | AO28: CRMS3913-H01 | AP28: 20977100
A29: 26 | B29: Polygon ZM | C29: 27 | D29: 15187944 | E29: 0.001159 | F29: 0.015414 | G29: 0.983428 | H29: 64100 | I29: 0 | J29: -1 | K29: 0.05 | L29: 10 | M29: 0 | N29: 106 | O29: 224 | P29: 1 | Q29: 0.023 | R29: 0.001 | S29: 1 | T29: 0 | U29: 0.008 | V29: 0.05 | W29: 0.05 | X29: 0.167428 | Y29: 0.363169 | Z29: 0.2 | AA29: 1 | AB29: -0.176035 | AC29: 0.176035 | AD29: 2D compartment | AE29: PB | AF29: 1 | AH29: 0.835 | AI29: -9999 | AK29: 0.25 | AO29: CRMS0056-H01 | AP29: 15187900
A30: 27 | B30: Polygon ZM | C30: 28 | D30: 40649267 | E30: 0.005001 | F30: 0.049757 | G30: 0.945241 | H30: 346200 | I30: 0 | J30: -0.230911 | K30: 0.05 | L30: 10 | M30: 0 | N30: 258 | O30: 210 | P30: 1 | Q30: 0.023 | R30: 0.001 | S30: 1 | T30: 0 | U30: 0.008 | V30: 0.05 | W30: 0.05 | X30: 0.04533 | Y30: 0.306926 | Z30: 0.2 | AA30: 1 | AB30: -0.170815 | AC30: 0.170815 | AD30: 2D compartment | AE30: PB | AF30: 1 | AH30: 0.835 | AI30: -9999 | AK30: 0.25 | AO30: CRMS0008-H02 | AP30: 40649300
A31: 28 | B31: Polygon ZM | C31: 29 | D31: 55791742 | E31: 0.003791 | F31: 0.05924 | G31: 0.936969 | H31: 367200 | I31: 0 | J31: -0.76398 | K31: 0.05 | L31: 10 | M31: 0 | N31: 215 | O31: 210 | P31: 1 | Q31: 0.023 | R31: 0.001 | S31: 1 | T31: 0 | U31: 0.008 | V31: 0.05 | W31: 0.05 | X31: 0.057462 | Y31: 0.475463 | Z31: 0.2 | AA31: 1 | AB31: -0.337036 | AC31: 0.337036 | AD31: 2D compartment | AE31: PB | AF31: 1 | AH31: 0.835 | AI31: -9999 | AK31: 0.25 | AO31: CRMS5267-H01 | AP31: 55791700
A32: 29 | B32: Polygon ZM | C32: 30 | D32: 32882479 | E32: 0.008543 | F32: 0.011453 | G32: 0.980005 | H32: 292200 | I32: 0 | J32: -1.938208 | K32: 0.05 | L32: 10 | M32: 0 | N32: 97 | O32: 225 | P32: 1 | Q32: 0.023 | R32: 0.001 | S32: 1 | T32: 0 | U32: 0.008 | V32: 0.05 | W32: 0.05 | X32: 0.098592 | Y32: 0.437258 | Z32: 0.2 | AA32: 1 | AB32: -0.166099 | AC32: 0.166099 | AD32: 2D compartment | AE32: PB | AF32: 1 | AH32: 0.835 | AI32: -9999 | AK32: 0.25 | AP32: 32882500
A33: 30 | B33: Polygon ZM | C33: 31 | D33: 19142288 | E33: 0.003375 | F33: 0.049132 | G33: 0.947493 | H33: 218700 | I33: 0 | J33: -0.42986 | K33: 0.05 | L33: 10 | M33: 0 | N33: 97 | O33: 225 | P33: 1 | Q33: 0.023 | R33: 0.001 | S33: 1 | T33: 0 | U33: 0.008 | V33: 0.05 | W33: 0.05 | X33: 0.063471 | Y33: 0.362347 | Z33: 0.2 | AA33: 1 | AB33: -0.211376 | AC33: 0.211376 | AD33: 2D compartment | AE33: PB | AF33: 1 | AH33: 0.835 | AI33: -9999 | AK33: 0.25 | AP33: 19142300
A34: 31 | B34: Polygon ZM | C34: 32 | D34: 63140202 | E34: 0.002319 | F34: 0.006272 | G34: 0.99141 | H34: 300100 | I34: 0 | J34: -0.782858 | K34: 0.05 | L34: 10 | M34: 0 | N34: 97 | O34: 225 | P34: 1 | Q34: 0.023 | R34: 0.001 | S34: 1 | T34: 0 | U34: 0.008 | V34: 0.05 | W34: 0.05 | X34: 0.041801 | Y34: 0.401041 | Z34: 0.2 | AA34: 1 | AB34: -0.101923 | AC34: 0.101923 | AD34: 2D compartment | AE34: PB | AF34: 1 | AH34: 0.835 | AI34: -9999 | AK34: 0.25 | AP34: 63140200
A35: 32 | B35: Polygon ZM | C35: 33 | D35: 261849984 | E35: 1 | F35: 0 | G35: 0 | H35: 1232600 | I35: 0 | J35: -2.832427 | K35: 0.05 | L35: 10 | M35: 0 | N35: 150 | O35: 224 | P35: 1 | Q35: 0.023 | R35: 0.001 | S35: 1 | T35: 0 | U35: 0.008 | V35: 0.05 | W35: 0.05 | X35: 0.048496 | Y35: 0.274281 | Z35: 0.2 | AA35: 1 | AB35: -0.2646 | AC35: 0.2646 | AD35: 2D tributary boundary (Qmult > 0) | AE35: PB | AF35: 0 | AH35: 0.835 | AI35: -9999 | AK35: 0.25 | AL35: S Lake Maurepas ungaged drainage | AM35: 34 | AN35: 0.5 | AO35: CRMS0034-H01 | AP35: 261850000
A36: 33 | B36: Polygon ZM | C36: 34 | D36: 145537009 | E36: 0.002992 | F36: 0.008077 | G36: 0.988931 | H36: 573300 | I36: 0 | J36: -5.33 | K36: 0.05 | L36: 10 | M36: 0 | N36: 80 | O36: 225 | P36: 1 | Q36: 0.023 | R36: 0.001 | S36: 1 | T36: 0 | U36: 0.008 | V36: 0.05 | W36: 0.05 | X36: 0.057159 | Y36: 0.425688 | Z36: 0.2 | AA36: 1 | AB36: -0.235331 | AC36: 0.235331 | AD36: 2D compartment | AE36: PB | AF36: 1 | AH36: 0.835 | AI36: -9999 | AK36: 0.25 | AO36: CRMS0030-H01 | AP36: 145537000
A37: 34 | B37: Polygon ZM | C37: 35 | D37: 16387070 | E37: 0.001404 | F37: 0.002923 | G37: 0.995673 | H37: 69700 | I37: 0 | J37: -0.746512 | K37: 0.05 | L37: 10 | M37: 0 | N37: 48 | O37: 239 | P37: 1 | Q37: 0.023 | R37: 0.001 | S37: 1 | T37: 0 | U37: 0.008 | V37: 0.05 | W37: 0.05 | X37: 0.087835 | Y37: 0.375839 | Z37: 0.2 | AA37: 1 | AB37: -0.109398 | AC37: 0.109398 | AD37: 2D compartment | AE37: PB | AF37: 1 | AH37: 0.835 | AI37: -9999 | AK37: 0.25 | AO37: CRMS0103-H01 | AP37: 16387100
A38: 35 | B38: Polygon ZM | C38: 36 | D38: 11178431 | E38: 0.004562 | F38: 0.006074 | G38: 0.989363 | H38: 80800 | I38: 0 | J38: -1 | K38: 0.05 | L38: 10 | M38: 0 | N38: 48 | O38: 253 | P38: 1 | Q38: 0.023 | R38: 0.001 | S38: 1 | T38: 0 | U38: 0.008 | V38: 0.05 | W38: 0.05 | X38: 0.062883 | Y38: 0.330344 | Z38: 0.2 | AA38: 1 | AB38: -0.117882 | AC38: 0.117882 | AD38: 2D compartment | AE38: PB | AF38: 1 | AH38: 0.835 | AI38: -9999 | AK38: 0.25 | AO38: CRMS4094-H01 | AP38: 11178400
A39: 36 | B39: Polygon ZM | C39: 37 | D39: 876906366 | E39: 1 | F39: 0 | G39: 0 | H39: 1086800 | I39: 0 | J39: -3.394203 | K39: 0.05 | L39: 10 | M39: 0 | N39: 106 | O39: 238 | P39: 1 | Q39: 0.023 | R39: 0.001 | S39: 1 | T39: 0 | U39: 0.008 | V39: 0.05 | W39: 0.05 | X39: 0.018745 | Y39: 0.63547 | Z39: 0.2 | AA39: 1 | AB39: -0.776585 | AC39: 0.776585 | AD39: 2D tributary boundary (Qmult > 0) | AE39: PB | AF39: 0 | AH39: 0.835 | AI39: -9999 | AK39: 0.25 | AL39: S/SW Lake Pontch ungaged drainage | AM39: 32 + 33 | AN39: 0.5 + 1 | AP39: 876905000
A40: 37 | B40: Polygon ZM | C40: 38 | D40: 672883641 | E40: 1 | F40: 0 | G40: 0 | H40: 720100 | I40: 0 | J40: -3.901745 | K40: 0.05 | L40: 10 | M40: 0 | N40: 45 | O40: 252 | P40: 1 | Q40: 0.023 | R40: 0.001 | S40: 1 | T40: 0 | U40: 0.008 | V40: 0.05 | W40: 0.05 | X40: 0.028301 | Y40: 0.73243 | Z40: 0.2 | AA40: 1 | AB40: -0.955561 | AC40: 0.955561 | AD40: 2D tributary boundary (Qmult > 0) | AE40: PB | AF40: 0 | AH40: 0.835 | AI40: -9999 | AK40: 0.25 | AL40: SE/S Lake Pontch ungaged drainage | AM40: 31 + 32 | AN40: 1 + 0.5 | AP40: 672884000
...

Sheet new
A1: attribute table from: Cells_processed_MP29_FY26Task5_rev01232026
A2: FID | B2: Shape | C2: ICM_ID | D2: TotalArea | E2: PercWater | F2: PercUpland | G2: PercMarsh | H2: MarshEdgeA | I2: RunoffMod | J2: bed_elev | K2: ero_bed_dp | L2: Bulk_dens | M2: percETcalc | N2: sand_adapt | O2: RunoffCoef | P2: RainGage29 | Q2: WindGage29 | R2: ETGage | S2: CurCoeff | T2: bedFricCoe | U2: NonSandExp | V2: NonSandCoe | W2: SandCoeff | X2: KadlacKa | Y2: KadlacKdep | Z2: MEErosion | AA2: offshorTSS | AB2: marsh_elev | AC2: marsh_ELsd | AD2: soil_moi_d | AE2: SedDepo_f | AF2: Eh_adj | AG2: ICM_region | AH2: Notes | AI2: LW_update | AJ2: Projectnam | AK2: TideGage | AL2: Tributary | AM2: Trib_Num | AN2: Qmult | AO2: AtcDeltaic | AP2: er_n | AQ2: er_short | AR2: er_name | AS2: HUC_12 | AT2: HU_12_NAME | AU2: RG_HUC12 | AV2: ET_HUC12 | AW2: deltaic | AX2: icmid | AY2: Eh_PCT10 | AZ2: Eh_PCT15 | BA2: Eh_PCT20 | BB2: Eh_PCT25 | BC2: Eh_PCT30 | BD2: Eh_PCT40 | BE2: Eh_PCT60 | BF2: area_m2
A3: 0 | B3: Polygon ZM | C3: 1 | D3: 103698642 | E3: 0.013791 | F3: 0.780092 | G3: 0.206117 | H3: 620100 | I3: 0 | J3: -0.6 | K3: 0.05 | L3: 0.835 | M3: 10 | N3: 0.25 | O3: 0 | P3: 1 | Q3: 1 | R3: 1 | S3: 0.023 | T3: 0.001 | U3: 1 | V3: 0 | W3: 0.008 | X3: 0.05 | Y3: 0.05 | Z3: 0 | AA3: -9999 | AB3: 2.240873 | AC3: 5.410236 | AD3: 0.2 | AE3: 1 | AF3: -1.688631 | AG3: PB-UL | AH3: 2D compartment | AI3: 1 | AO3: 0 | AP3: 1 | AQ3: MRP | AR3: Maurepas | AS3: 80702040201 | AT3: St James Parish Canal | AU3: 1862 | AV3: 2 | AW3: 1 | AX3: 1 | AY3: 0.48443 | AZ3: 0.552242 | BA3: 0.625477 | BB3: 0.703924 | BC3: 0.793758 | BD3: 1.008215 | BE3: 1.461356 | BF3: 103699000
A4: 1 | B4: Polygon ZM | C4: 2 | D4: 73299177 | E4: 0.001199 | F4: 0.035746 | G4: 0.963054 | H4: 25500 | I4: 0 | J4: -0.608021 | K4: 0.05 | L4: 0.835 | M4: 10 | N4: 0.25 | O4: 0 | P4: 2 | Q4: 2 | R4: 1 | S4: 0.023 | T4: 0.001 | U4: 1 | V4: 0 | W4: 0.008 | X4: 0.05 | Y4: 0.05 | Z4: 0 | AA4: -9999 | AB4: 0.636426 | AC4: 1.548429 | AD4: 0.2 | AE4: 1 | AF4: -0.256605 | AG4: PB | AH4: 2D compartment | AI4: 1 | AO4: 0 | AP4: 1 | AQ4: MRP | AR4: Maurepas | AS4: 80702040204 | AT4: Old New River-Blind River | AU4: 1863 | AV4: 2 | AW4: 1 | AX4: 2 | AY4: 0.370891 | AZ4: 0.382752 | BA4: 0.39224 | BB4: 0.401498 | BC4: 0.410915 | BD4: 0.432498 | BE4: 0.504575 | BF4: 73299200
A5: 2 | B5: Polygon ZM | C5: 3 | D5: 19385799 | E5: 5e-06 | F5: 0.036382 | G5: 0.963613 | H5: 1900 | I5: 0 | J5: -0.6 | K5: 0.05 | L5: 0.835 | M5: 10 | N5: 0.25 | O5: 0 | P5: 3 | Q5: 3 | R5: 1 | S5: 0.023 | T5: 0.001 | U5: 1 | V5: 0 | W5: 0.008 | X5: 0.05 | Y5: 0.05 | Z5: 0 | AA5: -9999 | AB5: 0.634869 | AC5: 0.148263 | AD5: 0.2 | AE5: 1 | AF5: -0.09858 | AG5: PB | AH5: 2D compartment | AI5: 1 | AJ5: West Maurepas Swamp | AO5: 0 | AP5: 1 | AQ5: MRP | AR5: Maurepas | AS5: 80702040204 | AT5: Old New River-Blind River | AU5: 1864 | AV5: 2 | AW5: 1 | AX5: 3 | AY5: 0.531159 | AZ5: 0.540428 | BA5: 0.548472 | BB5: 0.557615 | BC5: 0.568276 | BD5: 0.587144 | BE5: 0.622705 | BF5: 19385800
A6: 3 | B6: Polygon ZM | C6: 4 | D6: 20564566 | E6: 4.4e-05 | F6: 0.026894 | G6: 0.973062 | H6: 101700 | I6: 0 | J6: -0.6 | K6: 0.05 | L6: 0.835 | M6: 10 | N6: 0.25 | O6: 0 | P6: 4 | Q6: 4 | R6: 1 | S6: 0.023 | T6: 0.001 | U6: 1 | V6: 0 | W6: 0.008 | X6: 0.05 | Y6: 0.05 | Z6: 0 | AA6: -9999 | AB6: 0.677141 | AC6: 0.190857 | AD6: 0.2 | AE6: 1 | AF6: -0.14715 | AG6: PB | AH6: 2D compartment | AI6: 1 | AO6: 0 | AP6: 1 | AQ6: MRP | AR6: Maurepas | AS6: 80702040302 | AT6: Hope Canal-Pipeline Canal | AU6: 1865 | AV6: 2 | AW6: 1 | AX6: 4 | AY6: 0.506497 | AZ6: 0.529991 | BA6: 0.550175 | BB6: 0.567165 | BC6: 0.581951 | BD6: 0.613058 | BE6: 0.682778 | BF6: 20564600
A7: 4 | B7: Polygon ZM | C7: 5 | D7: 13723604 | E7: 0 | F7: 0.022851 | G7: 0.977149 | H7: 0 | I7: 0 | J7: -0.664898 | K7: 0.05 | L7: 0.835 | M7: 10 | N7: 0.25 | O7: 0 | P7: 5 | Q7: 5 | R7: 1 | S7: 0.023 | T7: 0.001 | U7: 1 | V7: 0 | W7: 0.008 | X7: 0.05 | Y7: 0.05 | Z7: 0 | AA7: -9999 | AB7: 0.461308 | AC7: 0.106401 | AD7: 0.2 | AE7: 1 | AF7: -0.060373 | AG7: PB | AH7: 2D compartment | AI7: 1 | AO7: 0 | AP7: 1 | AQ7: MRP | AR7: Maurepas | AS7: 80702040303 | AT7: Dutch Bayou-Mississippi Bayou | AU7: 1866 | AV7: 2 | AW7: 1 | AX7: 5 | AY7: 0.39394 | AZ7: 0.400935 | BA7: 0.407125 | BB7: 0.413499 | BC7: 0.41876 | BD7: 0.429045 | BE7: 0.450586 | BF7: 13723600
A8: 5 | B8: Polygon ZM | C8: 6 | D8: 37491882 | E8: 0.055188 | F8: 0.809231 | G8: 0.135581 | H8: 449100 | I8: 0 | J8: -0.6 | K8: 0.05 | L8: 0.835 | M8: 10 | N8: 0.25 | O8: 0 | P8: 6 | Q8: 6 | R8: 1 | S8: 0.023 | T8: 0.001 | U8: 1 | V8: 0 | W8: 0.008 | X8: 0.05 | Y8: 0.05 | Z8: 0 | AA8: -9999 | AB8: 3.007417 | AC8: 3.148099 | AD8: 0.2 | AE8: 1 | AF8: -2.167269 | AG8: PB-UL | AH8: 2D compartment | AI8: 1 | AO8: 0 | AP8: 1 | AQ8: MRP | AR8: Maurepas | AS8: 80702040302 | AT8: Hope Canal-Pipeline Canal | AU8: 1867 | AV8: 2 | AW8: 1 | AX8: 6 | AY8: 0.749989 | AZ8: 0.840148 | BA8: 0.923291 | BB8: 1.021128 | BC8: 1.131435 | BD8: 1.394102 | BE8: 2.582673 | BF8: 37491900
A9: 6 | B9: Polygon ZM | C9: 7 | D9: 16365869 | E9: 0.004289 | F9: 0.270085 | G9: 0.725626 | H9: 163800 | I9: 0 | J9: -0.6 | K9: 0.05 | L9: 0.835 | M9: 10 | N9: 0.25 | O9: 0 | P9: 7 | Q9: 7 | R9: 1 | S9: 0.023 | T9: 0.001 | U9: 1 | V9: 0 | W9: 0.008 | X9: 0.05 | Y9: 0.05 | Z9: 0 | AA9: -9999 | AB9: 0.726372 | AC9: 0.265652 | AD9: 0.2 | AE9: 1 | AF9: -0.139846 | AG9: PB | AH9: 2D compartment | AI9: 1 | AO9: 0 | AP9: 1 | AQ9: MRP | AR9: Maurepas | AS9: 80702040301 | AT9: Reserve Relief Canal | AU9: 1868 | AV9: 2 | AW9: 1 | AX9: 7 | AY9: 0.559353 | AZ9: 0.586526 | BA9: 0.601614 | BB9: 0.614574 | BC9: 0.627543 | BD9: 0.656232 | BE9: 0.724289 | BF9: 16365900
A10: 7 | B10: Polygon ZM | C10: 8 | D10: 21156458 | E10: 0.00536 | F10: 0.556476 | G10: 0.438164 | H10: 306900 | I10: 0 | J10: -0.6 | K10: 0.05 | L10: 0.835 | M10: 10 | N10: 0.25 | O10: 0 | P10: 8 | Q10: 8 | R10: 1 | S10: 0.023 | T10: 0.001 | U10: 1 | V10: 0 | W10: 0.008 | X10: 0.05 | Y10: 0.05 | Z10: 0 | AA10: -9999 | AB10: 0.74742 | AC10: 0.316696 | AD10: 0.2 | AE10: 1 | AF10: -0.204341 | AG10: PB | AH10: 2D compartment | AI10: 1 | AO10: 0 | AP10: 1 | AQ10: MRP | AR10: Maurepas | AS10: 80702040301 | AT10: Reserve Relief Canal | AU10: 1869 | AV10: 2 | AW10: 1 | AX10: 8 | AY10: 0.514893 | AZ10: 0.54308 | BA10: 0.568018 | BB10: 0.589526 | BC10: 0.604912 | BD10: 0.629149 | BE10: 0.69409 | BF10: 21156500
A11: 8 | B11: Polygon ZM | C11: 9 | D11: 22013590 | E11: 0.001962 | F11: 0.39586 | G11: 0.602178 | H11: 96300 | I11: 0 | J11: -0.6 | K11: 0.05 | L11: 0.835 | M11: 10 | N11: 0.25 | O11: 0 | P11: 9 | Q11: 9 | R11: 1 | S11: 0.023 | T11: 0.001 | U11: 1 | V11: 0 | W11: 0.008 | X11: 0.05 | Y11: 0.05 | Z11: 0.014247 | AA11: -9999 | AB11: 0.757179 | AC11: 0.387037 | AD11: 0.2 | AE11: 1 | AF11: -0.288093 | AG11: PB | AH11: 2D compartment | AI11: 1 | AO11: 0 | AP11: 1 | AQ11: MRP | AR11: Maurepas | AS11: 80702040503 | AT11: Illinois Central Gulf | AU11: 1870 | AV11: 2 | AW11: 1 | AX11: 9 | AY11: 0.419097 | AZ11: 0.469086 | BA11: 0.510282 | BB11: 0.540736 | BC11: 0.565733 | BD11: 0.612844 | BE11: 0.704323 | BF11: 22013600
A12: 9 | B12: Polygon ZM | C12: 10 | D12: 24574494 | E12: 0.000549 | F12: 0.797253 | G12: 0.202197 | H12: 26100 | I12: 0 | J12: -0.6 | K12: 0.05 | L12: 0.835 | M12: 10 | N12: 0.25 | O12: 0 | P12: 10 | Q12: 10 | R12: 1 | S12: 0.023 | T12: 0.001 | U12: 1 | V12: 0 | W12: 0.008 | X12: 0.05 | Y12: 0.05 | Z12: 0 | AA12: -9999 | AB12: 2.038979 | AC12: 0.958388 | AD12: 0.2 | AE12: 1 | AF12: -1.060347 | AG12: PB-UL | AH12: 2D compartment | AI12: 1 | AO12: 0 | AP12: 1 | AQ12: MRP | AR12: Maurepas | AS12: 80701000105 | AT12: Claiborne Island | AU12: 1871 | AV12: 2 | AW12: 1 | AX12: 10 | AY12: 0.798655 | AZ12: 0.978632 | BA12: 1.11345 | BB12: 1.237733 | BC12: 1.38246 | BD12: 1.661375 | BE12: 2.411322 | BF12: 24574500
A13: 10 | B13: Polygon ZM | C13: 11 | D13: 28238972 | E13: 0.074769 | F13: 0.072399 | G13: 0.852832 | H13: 2475000 | I13: 0 | J13: -0.6 | K13: 0.05 | L13: 0.835 | M13: 10 | N13: 0.25 | O13: 0 | P13: 11 | Q13: 11 | R13: 1 | S13: 0.023 | T13: 0.001 | U13: 1 | V13: 0 | W13: 0.008 | X13: 0.05 | Y13: 0.05 | Z13: 0.083592 | AA13: -9999 | AB13: 0.966667 | AC13: 0.662012 | AD13: 0.2 | AE13: 1 | AF13: -0.464109 | AG13: PB | AH13: 2D tributary boundary (Qmult > 0) | AI13: 1 | AL13: Bonnet Carre Spillway | AM13: 42 | AN13: 1 | AO13: 0 | AP13: 2 | AQ13: LPO | AR13: Lake_Pontchartrain | AS13: 80902030101 | AT13: Bayou La Branche-Frontal Lake Pontchartrain | AU13: 11 | AV13: 1 | AW13: 1 | AX13: 11 | AY13: 0.44248 | AZ13: 0.502558 | BA13: 0.542885 | BB13: 0.574442 | BC13: 0.602954 | BD13: 0.659676 | BE13: 0.856097 | BF13: 28239000
A14: 11 | B14: Polygon ZM | C14: 12 | D14: 30197797 | E14: 0.153548 | F14: 0.036036 | G14: 0.810417 | H14: 1860300 | I14: 0 | J14: -0.6 | K14: 0.05 | L14: 0.835 | M14: 10 | N14: 0.25 | O14: 0 | P14: 12 | Q14: 12 | R14: 1 | S14: 0.023 | T14: 0.001 | U14: 1 | V14: 0 | W14: 0.008 | X14: 0.05 | Y14: 0.05 | Z14: 0.101319 | AA14: -9999 | AB14: 0.273232 | AC14: 0.415433 | AD14: 0.2 | AE14: 1 | AF14: -0.476995 | AG14: PB | AH14: 2D tributary boundary (Qmult > 0) | AI14: 1 | AL14: LaBranche Hydrologic Restoration | AM14: 44 | AN14: 1 | AO14: 0 | AP14: 2 | AQ14: LPO | AR14: Lake_Pontchartrain | AS14: 80902030101 | AT14: Bayou La Branche-Frontal Lake Pontchartrain | AU14: 12 | AV14: 1 | AW14: 1 | AX14: 12 | AY14: -0.5758 | AZ14: -0.203764 | BA14: 0.130337 | BB14: 0.2096 | BC14: 0.261455 | BD14: 0.335372 | BE14: 0.426812 | BF14: 30197800
A15: 12 | B15: Polygon ZM | C15: 13 | D15: 227355705 | E15: 4e-06 | F15: 0.999972 | G15: 2.4e-05 | H15: 5400 | I15: 0 | J15: -3.5179 | K15: 0.05 | L15: 0.835 | M15: 10 | N15: 0.25 | O15: 0 | P15: 13 | Q15: 13 | R15: 1 | S15: 0.023 | T15: 0.001 | U15: 1 | V15: 0 | W15: 0.008 | X15: 0.05 | Y15: 0.05 | Z15: 0.004667 | AA15: -9999 | AB15: 0.134316 | AC15: 0.600969 | AD15: 0.2 | AE15: 1 | AF15: -0.468709 | AG15: PB-UL | AH15: 2D compartment | AI15: 1 | AO15: 0 | AP15: 33 | AQ15: -9999 | AR15: -9999 | AS15: 80902030103 | AT15: Metairie Canal-Canal No 2 | AU15: 1872 | AV15: 2 | AW15: -9999 | AX15: 13 | AY15: -0.527464 | AZ15: -0.334393 | BA15: -0.141322 | BB15: -0.12069 | BC15: -0.100058 | BD15: -0.058793 | BE15: 0.28528 | BF15: 227356000
A16: 13 | B16: Polygon ZM | C16: 14 | D16: 59310369 | E16: 0 | F16: 0.999985 | G16: 1.5e-05 | H16: 0 | I16: 0 | J16: -4.083467 | K16: 0.05 | L16: 0.835 | M16: 10 | N16: 0.25 | O16: 0 | P16: 14 | Q16: 14 | R16: 1 | S16: 0.023 | T16: 0.001 | U16: 1 | V16: 0 | W16: 0.008 | X16: 0.05 | Y16: 0.05 | Z16: 0.048285 | AA16: -9999 | AB16: 1.757205 | AC16: 0.624743 | AD16: 0.2 | AE16: 1 | AF16: -0.532779 | AG16: PB-UL | AH16: 2D compartment | AI16: 1 | AO16: 0 | AP16: 2 | AQ16: LPO | AR16: Lake_Pontchartrain | AS16: 80902030201 | AT16: Morrison Canal | AU16: 1873 | AV16: 2 | AW16: 1 | AX16: 14 | AY16: 1.154533 | AZ16: 1.224426 | BA16: 1.294319 | BB16: 1.364212 | BC16: 1.434106 | BD16: 1.573892 | BE16: 1.879581 | BF16: 59310400
A17: 14 | B17: Polygon ZM | C17: 15 | D17: 43748405 | E17: 0.009776 | F17: 0.014154 | G17: 0.97607 | H17: 176500 | I17: 0 | J17: -2.86 | K17: 0.05 | L17: 0.835 | M17: 10 | N17: 0.25 | O17: 0 | P17: 15 | Q17: 15 | R17: 1 | S17: 0.023 | T17: 0.001 | U17: 1 | V17: 0 | W17: 0.008 | X17: 0.05 | Y17: 0.05 | Z17: 0.077421 | AA17: -9999 | AB17: 0.62615 | AC17: 0.19221 | AD17: 0.2 | AE17: 1 | AF17: -0.217066 | AG17: PB | AH17: 2D tributary boundary (Qmult > 0) | AI17: 1 | AJ17: West Maurepas Swamp | AL17: Union & West Maurepas Diversion | AM17: 38 + 39 | AN17: 1 + 1 | AO17: 0 | AP17: 1 | AQ17: MRP | AR17: Maurepas | AS17: 80702040104 | AT17: Bayou Pierre-Little Amite River | AU17: 1874 | AV17: 2 | AW17: 1 | AX17: 15 | AY17: 0.578478 | AZ17: 0.592289 | BA17: 0.604455 | BB17: 0.615639 | BC17: 0.626448 | BD17: 0.647185 | BE17: 0.690694 | BF17: 43748400
A18: 15 | B18: Polygon ZM | C18: 16 | D18: 21927368 | E18: 0 | F18: 0.003971 | G18: 0.996029 | H18: 68400 | I18: 0 | J18: -0.775204 | K18: 0.05 | L18: 0.835 | M18: 10 | N18: 0.25 | O18: 0 | P18: 16 | Q18: 16 | R18: 1 | S18: 0.023 | T18: 0.001 | U18: 1 | V18: 0 | W18: 0.008 | X18: 0.05 | Y18: 0.05 | Z18: 0 | AA18: -9999 | AB18: 0.630183 | AC18: 0.141811 | AD18: 0.2 | AE18: 1 | AF18: -0.092683 | AG18: PB | AH18: 2D tributary boundary (Qmult > 0) | AI18: 1 | AJ18: West Maurepas Swamp | AL18: East Maurepas Diversion | AM18: 40 | AN18: 0.5 | AO18: 1 | AP18: 1 | AQ18: MRP | AR18: Maurepas | AS18: 80702040204 | AT18: Old New River-Blind River | AU18: 16 | AV18: 1 | AW18: 1 | AX18: 16 | AY18: 0.523857 | AZ18: 0.5375 | BA18: 0.548532 | BB18: 0.559349 | BC18: 0.569294 | BD18: 0.590274 | BE18: 0.642266 | BF18: 21927400
A19: 16 | B19: Polygon ZM | C19: 17 | D19: 21732064 | E19: 0.000124 | F19: 0 | G19: 0.999876 | H19: 172800 | I19: 0 | J19: -2.494671 | K19: 0.05 | L19: 0.835 | M19: 10 | N19: 0.25 | O19: 0 | P19: 17 | Q19: 17 | R19: 1 | S19: 0.023 | T19: 0.001 | U19: 1 | V19: 0 | W19: 0.008 | X19: 0.05 | Y19: 0.05 | Z19: 0.039294 | AA19: -9999 | AB19: 0.68808 | AC19: 0.086616 | AD19: 0.2 | AE19: 1 | AF19: -0.089609 | AG19: PB | AH19: 2D compartment | AI19: 1 | AJ19: West Maurepas Swamp | AO19: 1 | AP19: 1 | AQ19: MRP | AR19: Maurepas | AS19: 80702040303 | AT19: Dutch Bayou-Mississippi Bayou | AU19: 17 | AV19: 1 | AW19: 1 | AX19: 17 | AY19: 0.572429 | AZ19: 0.59847 | BA19: 0.616301 | BB19: 0.631968 | BC19: 0.646236 | BD19: 0.671023 | BE19: 0.714629 | BF19: 21732100
A20: 17 | B20: Polygon ZM | C20: 18 | D20: 30146863 | E20: 0.004986 | F20: 4.5e-05 | G20: 0.994969 | H20: 487800 | I20: 0 | J20: -2.203318 | K20: 0.05 | L20: 0.835 | M20: 10 | N20: 0.25 | O20: 0 | P20: 18 | Q20: 18 | R20: 1 | S20: 0.023 | T20: 0.001 | U20: 1 | V20: 0 | W20: 0.008 | X20: 0.05 | Y20: 0.05 | Z20: 0.091101 | AA20: -9999 | AB20: 0.653932 | AC20: 0.085099 | AD20: 0.2 | AE20: 1 | AF20: -0.076621 | AG20: PB | AH20: 2D compartment | AI20: 1 | AJ20: West Maurepas Swamp | AO20: 1 | AP20: 1 | AQ20: MRP | AR20: Maurepas | AS20: 80702040303 | AT20: Dutch Bayou-Mississippi Bayou | AU20: 18 | AV20: 1 | AW20: 1 | AX20: 18 | AY20: 0.560404 | AZ20: 0.577311 | BA20: 0.589915 | BB20: 0.60128 | BC20: 0.611014 | BD20: 0.630232 | BE20: 0.67115 | BF20: 30146900
A21: 18 | B21: Polygon ZM | C21: 19 | D21: 25767723 | E21: 0 | F21: 0.003591 | G21: 0.996409 | H21: 0 | I21: 0 | J21: -0.6 | K21: 0.05 | L21: 0.835 | M21: 10 | N21: 0.25 | O21: 0 | P21: 19 | Q21: 19 | R21: 1 | S21: 0.023 | T21: 0.001 | U21: 1 | V21: 0 | W21: 0.008 | X21: 0.05 | Y21: 0.05 | Z21: 0 | AA21: -9999 | AB21: 0.600003 | AC21: 0.146763 | AD21: 0.2 | AE21: 1 | AF21: -0.112847 | AG21: PB | AH21: 2D tributary boundary (Qmult > 0) | AI21: 1 | AJ21: West Maurepas Swamp | AL21: East Maurepas Diversion | AM21: 40 | AN21: 0.5 | AO21: 1 | AP21: 1 | AQ21: MRP | AR21: Maurepas | AS21: 80702040303 | AT21: Dutch Bayou-Mississippi Bayou | AU21: 19 | AV21: 1 | AW21: 1 | AX21: 19 | AY21: 0.460646 | AZ21: 0.487156 | BA21: 0.504003 | BB21: 0.519193 | BC21: 0.532579 | BD21: 0.56612 | BE21: 0.623441 | BF21: 25767700
A22: 19 | B22: Polygon ZM | C22: 20 | D22: 11803852 | E22: 0.000305 | F22: 0.001174 | G22: 0.998521 | H22: 33300 | I22: 0 | J22: -0.6 | K22: 0.05 | L22: 0.835 | M22: 10 | N22: 0.25 | O22: 0 | P22: 20 | Q22: 20 | R22: 1 | S22: 0.023 | T22: 0.001 | U22: 1 | V22: 0 | W22: 0.008 | X22: 0.05 | Y22: 0.05 | Z22: 0.070701 | AA22: -9999 | AB22: 0.681026 | AC22: 0.085225 | AD22: 0.2 | AE22: 1 | AF22: -0.079664 | AG22: PB | AH22: 2D compartment | AI22: 1 | AJ22: West Maurepas Swamp | AO22: 1 | AP22: 1 | AQ22: MRP | AR22: Maurepas | AS22: 80702040303 | AT22: Dutch Bayou-Mississippi Bayou | AU22: 20 | AV22: 1 | AW22: 1 | AX22: 20 | AY22: 0.583824 | AZ22: 0.601362 | BA22: 0.614844 | BB22: 0.625641 | BC22: 0.636365 | BD22: 0.656891 | BE22: 0.697133 | BF22: 11803900
A23: 20 | B23: Polygon ZM | C23: 21 | D23: 14083304 | E23: 0 | F23: 0.003011 | G23: 0.996989 | H23: 67500 | I23: 0 | J23: -0.6 | K23: 0.05 | L23: 0.835 | M23: 10 | N23: 0.25 | O23: 0 | P23: 21 | Q23: 21 | R23: 1 | S23: 0.023 | T23: 0.001 | U23: 1 | V23: 0 | W23: 0.008 | X23: 0.05 | Y23: 0.05 | Z23: 0 | AA23: -9999 | AB23: 0.668911 | AC23: 0.1166 | AD23: 0.2 | AE23: 1 | AF23: -0.102561 | AG23: PB | AH23: 2D compartment | AI23: 1 | AO23: 1 | AP23: 1 | AQ23: MRP | AR23: Maurepas | AS23: 80702040301 | AT23: Reserve Relief Canal | AU23: 21 | AV23: 1 | AW23: 1 | AX23: 21 | AY23: 0.5487 | AZ23: 0.56635 | BA23: 0.583328 | BB23: 0.59929 | BC23: 0.614393 | BD23: 0.640845 | BE23: 0.686369 | BF23: 14083300
A24: 21 | B24: Polygon ZM | C24: 22 | D24: 9098213 | E24: 0.00089 | F24: 0 | G24: 0.99911 | H24: 80100 | I24: 0 | J24: -0.6 | K24: 0.05 | L24: 0.835 | M24: 10 | N24: 0.25 | O24: 0 | P24: 22 | Q24: 22 | R24: 1 | S24: 0.023 | T24: 0.001 | U24: 1 | V24: 0 | W24: 0.008 | X24: 0.05 | Y24: 0.05 | Z24: 0.0332 | AA24: -9999 | AB24: 0.716641 | AC24: 0.09926 | AD24: 0.2 | AE24: 1 | AF24: -0.096612 | AG24: PB | AH24: 2D compartment | AI24: 1 | AO24: 1 | AP24: 1 | AQ24: MRP | AR24: Maurepas | AS24: 80702040301 | AT24: Reserve Relief Canal | AU24: 22 | AV24: 1 | AW24: 1 | AX24: 22 | AY24: 0.60347 | AZ24: 0.62003 | BA24: 0.634442 | BB24: 0.648681 | BC24: 0.662783 | BD24: 0.688103 | BE24: 0.733808 | BF24: 9098210
A25: 22 | B25: Polygon ZM | C25: 23 | D25: 16012338 | E25: 5.6e-05 | F25: 0.000533 | G25: 0.999411 | H25: 63900 | I25: 0 | J25: -0.6 | K25: 0.05 | L25: 0.835 | M25: 10 | N25: 0.25 | O25: 0 | P25: 23 | Q25: 23 | R25: 1 | S25: 0.023 | T25: 0.001 | U25: 1 | V25: 0 | W25: 0.008 | X25: 0.05 | Y25: 0.05 | Z25: 0 | AA25: -9999 | AB25: 0.67254 | AC25: 0.129651 | AD25: 0.2 | AE25: 1 | AF25: -0.121549 | AG25: PB | AH25: 2D compartment | AI25: 1 | AO25: 0 | AP25: 1 | AQ25: MRP | AR25: Maurepas | AS25: 80702040301 | AT25: Reserve Relief Canal | AU25: 23 | AV25: 1 | AW25: 1 | AX25: 23 | AY25: 0.529564 | AZ25: 0.550991 | BA25: 0.5688 | BB25: 0.585312 | BC25: 0.601747 | BD25: 0.634209 | BE25: 0.699574 | BF25: 16012300
A26: 23 | B26: Polygon ZM | C26: 24 | D26: 13970240 | E26: 0.007795 | F26: 9.6e-05 | G26: 0.992109 | H26: 208800 | I26: 0 | J26: -0.6 | K26: 0.05 | L26: 0.835 | M26: 10 | N26: 0.25 | O26: 0 | P26: 24 | Q26: 24 | R26: 1 | S26: 0.023 | T26: 0.001 | U26: 1 | V26: 0 | W26: 0.008 | X26: 0.05 | Y26: 0.05 | Z26: 0.090165 | AA26: -9999 | AB26: 0.749764 | AC26: 0.10024 | AD26: 0.2 | AE26: 1 | AF26: -0.093942 | AG26: PB | AH26: 2D compartment | AI26: 1 | AO26: 0 | AP26: 1 | AQ26: MRP | AR26: Maurepas | AS26: 80702040301 | AT26: Reserve Relief Canal | AU26: 24 | AV26: 1 | AW26: 1 | AX26: 24 | AY26: 0.634684 | AZ26: 0.655822 | BA26: 0.673875 | BB26: 0.687676 | BC26: 0.700896 | BD26: 0.725249 | BE26: 0.769427 | BF26: 13970200
A27: 24 | B27: Polygon ZM | C27: 25 | D27: 16220799 | E27: 5.5e-05 | F27: 6.2e-05 | G27: 0.999883 | H27: 71100 | I27: 0 | J27: -0.6 | K27: 0.05 | L27: 0.835 | M27: 10 | N27: 0.25 | O27: 0 | P27: 25 | Q27: 25 | R27: 1 | S27: 0.023 | T27: 0.001 | U27: 1 | V27: 0 | W27: 0.008 | X27: 0.05 | Y27: 0.05 | Z27: 0.000994 | AA27: -9999 | AB27: 0.615606 | AC27: 0.096457 | AD27: 0.2 | AE27: 1 | AF27: -0.090966 | AG27: PB | AH27: 2D compartment | AI27: 1 | AO27: 0 | AP27: 1 | AQ27: MRP | AR27: Maurepas | AS27: 80702040301 | AT27: Reserve Relief Canal | AU27: 25 | AV27: 1 | AW27: 1 | AX27: 25 | AY27: 0.506713 | AZ27: 0.52464 | BA27: 0.539175 | BB27: 0.551707 | BC27: 0.563169 | BD27: 0.584712 | BE27: 0.62861 | BF27: 16220800
A28: 25 | B28: Polygon ZM | C28: 26 | D28: 20977096 | E28: 0.005578 | F28: 0.000424 | G28: 0.993998 | H28: 258300 | I28: 0 | J28: -0.6 | K28: 0.05 | L28: 0.835 | M28: 10 | N28: 0.25 | O28: 0 | P28: 26 | Q28: 26 | R28: 1 | S28: 0.023 | T28: 0.001 | U28: 1 | V28: 0 | W28: 0.008 | X28: 0.05 | Y28: 0.05 | Z28: 0.174654 | AA28: -9999 | AB28: 0.711468 | AC28: 0.116869 | AD28: 0.2 | AE28: 1 | AF28: -0.123564 | AG28: PB | AH28: 2D compartment | AI28: 1 | AO28: 0 | AP28: 1 | AQ28: MRP | AR28: Maurepas | AS28: 80702040503 | AT28: Illinois Central Gulf | AU28: 26 | AV28: 1 | AW28: 1 | AX28: 26 | AY28: 0.565203 | AZ28: 0.587904 | BA28: 0.611067 | BB28: 0.631588 | BC28: 0.650188 | BD28: 0.680274 | BE28: 0.732033 | BF28: 20977100
A29: 26 | B29: Polygon ZM | C29: 27 | D29: 15187944 | E29: 0.002667 | F29: 0.013303 | G29: 0.98403 | H29: 230400 | I29: 0 | J29: -1 | K29: 0.05 | L29: 0.835 | M29: 10 | N29: 0.25 | O29: 0 | P29: 27 | Q29: 27 | R29: 1 | S29: 0.023 | T29: 0.001 | U29: 1 | V29: 0 | W29: 0.008 | X29: 0.05 | Y29: 0.05 | Z29: 0.167428 | AA29: -9999 | AB29: 0.725782 | AC29: 0.154015 | AD29: 0.2 | AE29: 1 | AF29: -0.130795 | AG29: PB | AH29: 2D compartment | AI29: 1 | AO29: 0 | AP29: 1 | AQ29: MRP | AR29: Maurepas | AS29: 80702040503 | AT29: Illinois Central Gulf | AU29: 27 | AV29: 1 | AW29: 1 | AX29: 27 | AY29: 0.574118 | AZ29: 0.594987 | BA29: 0.618108 | BB29: 0.635774 | BC29: 0.650801 | BD29: 0.679341 | BE29: 0.739437 | BF29: 15187900
A30: 27 | B30: Polygon ZM | C30: 28 | D30: 40649267 | E30: 0.002125 | F30: 0.049968 | G30: 0.947906 | H30: 264600 | I30: 0 | J30: -0.6 | K30: 0.05 | L30: 0.835 | M30: 10 | N30: 0.25 | O30: 0 | P30: 28 | Q30: 28 | R30: 1 | S30: 0.023 | T30: 0.001 | U30: 1 | V30: 0 | W30: 0.008 | X30: 0.05 | Y30: 0.05 | Z30: 0.04533 | AA30: -9999 | AB30: 0.557003 | AC30: 0.158054 | AD30: 0.2 | AE30: 1 | AF30: -0.102077 | AG30: PB | AH30: 2D compartment | AI30: 1 | AO30: 0 | AP30: 1 | AQ30: MRP | AR30: Maurepas | AS30: 80702040205 | AT30: Bayou Chene Blanc-Blind River | AU30: 1875 | AV30: 2 | AW30: 1 | AX30: 28 | AY30: 0.442422 | AZ30: 0.454926 | BA30: 0.465218 | BB30: 0.474646 | BC30: 0.483655 | BD30: 0.500172 | BE30: 0.541404 | BF30: 40649300
A31: 28 | B31: Polygon ZM | C31: 29 | D31: 55791742 | E31: 0.002968 | F31: 0.060425 | G31: 0.936606 | H31: 792000 | I31: 0 | J31: -0.76398 | K31: 0.05 | L31: 0.835 | M31: 10 | N31: 0.25 | O31: 0 | P31: 29 | Q31: 29 | R31: 1 | S31: 0.023 | T31: 0.001 | U31: 1 | V31: 0 | W31: 0.008 | X31: 0.05 | Y31: 0.05 | Z31: 0.057462 | AA31: -9999 | AB31: 0.652144 | AC31: 0.298944 | AD31: 0.2 | AE31: 1 | AF31: -0.158386 | AG31: PB | AH31: 2D compartment | AI31: 1 | AO31: 0 | AP31: 1 | AQ31: MRP | AR31: Maurepas | AS31: 80702040205 | AT31: Bayou Chene Blanc-Blind River | AU31: 29 | AV31: 1 | AW31: 1 | AX31: 29 | AY31: 0.473847 | AZ31: 0.493757 | BA31: 0.509875 | BB31: 0.524466 | BC31: 0.537875 | BD31: 0.563438 | BE31: 0.618965 | BF31: 55791700
A32: 29 | B32: Polygon ZM | C32: 30 | D32: 32882479 | E32: 0.006213 | F32: 0.017656 | G32: 0.976131 | H32: 808200 | I32: 0 | J32: -1.938208 | K32: 0.05 | L32: 0.835 | M32: 10 | N32: 0.25 | O32: 0 | P32: 30 | Q32: 30 | R32: 1 | S32: 0.023 | T32: 0.001 | U32: 1 | V32: 0 | W32: 0.008 | X32: 0.05 | Y32: 0.05 | Z32: 0.098592 | AA32: -9999 | AB32: 0.556546 | AC32: 0.163538 | AD32: 0.2 | AE32: 1 | AF32: -0.102089 | AG32: PB | AH32: 2D compartment | AI32: 1 | AO32: 0 | AP32: 1 | AQ32: MRP | AR32: Maurepas | AS32: 80702030403 | AT32: Killian Bayou-Tickfaw River | AU32: 30 | AV32: 1 | AW32: 1 | AX32: 30 | AY32: 0.432657 | AZ32: 0.454457 | BA32: 0.472242 | BB32: 0.487465 | BC32: 0.500501 | BD32: 0.524132 | BE32: 0.572393 | BF32: 32882500
A33: 30 | B33: Polygon ZM | C33: 31 | D33: 19142288 | E33: 0.000893 | F33: 0.073966 | G33: 0.92514 | H33: 576900 | I33: 0 | J33: -0.6 | K33: 0.05 | L33: 0.835 | M33: 10 | N33: 0.25 | O33: 0 | P33: 31 | Q33: 31 | R33: 1 | S33: 0.023 | T33: 0.001 | U33: 1 | V33: 0 | W33: 0.008 | X33: 0.05 | Y33: 0.05 | Z33: 0.063471 | AA33: -9999 | AB33: 0.521154 | AC33: 0.191166 | AD33: 0.2 | AE33: 1 | AF33: -0.098054 | AG33: PB | AH33: 2D compartment | AI33: 1 | AO33: 0 | AP33: 1 | AQ33: MRP | AR33: Maurepas | AS33: 80702030403 | AT33: Killian Bayou-Tickfaw River | AU33: 31 | AV33: 1 | AW33: 1 | AX33: 31 | AY33: 0.406897 | AZ33: 0.4231 | BA33: 0.433939 | BB33: 0.442999 | BC33: 0.451958 | BD33: 0.470502 | BE33: 0.516217 | BF33: 19142300
A34: 31 | B34: Polygon ZM | C34: 32 | D34: 63140202 | E34: 0.00114 | F34: 0.02105 | G34: 0.97781 | H34: 564300 | I34: 0 | J34: -0.826819 | K34: 0.05 | L34: 0.835 | M34: 10 | N34: 0.25 | O34: 0 | P34: 32 | Q34: 32 | R34: 1 | S34: 0.023 | T34: 0.001 | U34: 1 | V34: 0 | W34: 0.008 | X34: 0.05 | Y34: 0.05 | Z34: 0.041801 | AA34: -9999 | AB34: 0.500085 | AC34: 0.115527 | AD34: 0.2 | AE34: 1 | AF34: -0.090262 | AG34: PB | AH34: 2D compartment | AI34: 1 | AO34: 0 | AP34: 1 | AQ34: MRP | AR34: Maurepas | AS34: 80702040502 | AT34: Anderson Canal | AU34: 32 | AV34: 1 | AW34: 1 | AX34: 32 | AY34: 0.386882 | AZ34: 0.409823 | BA34: 0.427422 | BB34: 0.442333 | BC34: 0.456549 | BD34: 0.486106 | BE34: 0.535727 | BF34: 63140200
A35: 32 | B35: Polygon ZM | C35: 33 | D35: 261849984 | E35: 0.928834 | F35: 0.002679 | G35: 0.068487 | H35: 2241000 | I35: 0 | J35: -2.832427 | K35: 0.05 | L35: 0.835 | M35: 10 | N35: 0.25 | O35: 0 | P35: 33 | Q35: 33 | R35: 1 | S35: 0.023 | T35: 0.001 | U35: 1 | V35: 0 | W35: 0.008 | X35: 0.05 | Y35: 0.05 | Z35: 0.048496 | AA35: -9999 | AB35: 0.364325 | AC35: 0.487942 | AD35: 0.2 | AE35: 1 | AF35: -0.034325 | AG35: PB | AH35: 2D tributary boundary (Qmult > 0) | AI35: 1 | AL35: S Lake Maurepas ungaged drainage | AM35: 34 | AN35: 0.5 | AO35: 0 | AP35: 1 | AQ35: MRP | AR35: Maurepas | AS35: 80702040400 | AU35: 33 | AV35: 1 | AW35: 1 | AX35: 33 | AY35: 0.311015 | AZ35: 0.33 | BA35: 0.342571 | BB35: 0.354328 | BC35: 0.364287 | BD35: 0.382285 | BE35: 0.415218 | BF35: 261850000
A36: 33 | B36: Polygon ZM | C36: 34 | D36: 145537009 | E36: 0.002387 | F36: 0.020313 | G36: 0.9773 | H36: 1140300 | I36: 0 | J36: -5.33 | K36: 0.05 | L36: 0.835 | M36: 10 | N36: 0.25 | O36: 0 | P36: 34 | Q36: 34 | R36: 1 | S36: 0.023 | T36: 0.001 | U36: 1 | V36: 0 | W36: 0.008 | X36: 0.05 | Y36: 0.05 | Z36: 0.057159 | AA36: -9999 | AB36: 0.555841 | AC36: 0.243693 | AD36: 0.2 | AE36: 1 | AF36: -0.142674 | AG36: PB | AH36: 2D compartment | AI36: 1 | AO36: 0 | AP36: 1 | AQ36: MRP | AR36: Maurepas | AS36: 80702040504 | AT36: North Pass-Manchac Pass | AU36: 34 | AV36: 1 | AW36: 1 | AX36: 34 | AY36: 0.392502 | AZ36: 0.413167 | BA36: 0.431183 | BB36: 0.447644 | BC36: 0.464079 | BD36: 0.496792 | BE36: 0.548677 | BF36: 145537000
A37: 34 | B37: Polygon ZM | C37: 35 | D37: 16387070 | E37: 0.000934 | F37: 0.007406 | G37: 0.99166 | H37: 219600 | I37: 0 | J37: -1.549925 | K37: 0.05 | L37: 0.835 | M37: 10 | N37: 0.25 | O37: 0 | P37: 35 | Q37: 35 | R37: 1 | S37: 0.023 | T37: 0.001 | U37: 1 | V37: 0 | W37: 0.008 | X37: 0.05 | Y37: 0.05 | Z37: 0.087835 | AA37: -9999 | AB37: 0.497252 | AC37: 0.127394 | AD37: 0.2 | AE37: 1 | AF37: -0.087106 | AG37: PB | AH37: 2D compartment | AI37: 1 | AO37: 0 | AP37: 2 | AQ37: LPO | AR37: Lake_Pontchartrain | AS37: 80702050402 | AT37: Bedico Creek | AU37: 35 | AV37: 1 | AW37: 1 | AX37: 35 | AY37: 0.395686 | AZ37: 0.410146 | BA37: 0.421365 | BB37: 0.431072 | BC37: 0.440285 | BD37: 0.458211 | BE37: 0.497382 | BF37: 16387100
A38: 35 | B38: Polygon ZM | C38: 36 | D38: 11178431 | E38: 0.000322 | F38: 0.007687 | G38: 0.991991 | H38: 97200 | I38: 0 | J38: -1 | K38: 0.05 | L38: 0.835 | M38: 10 | N38: 0.25 | O38: 0 | P38: 36 | Q38: 36 | R38: 1 | S38: 0.023 | T38: 0.001 | U38: 1 | V38: 0 | W38: 0.008 | X38: 0.05 | Y38: 0.05 | Z38: 0.062883 | AA38: -9999 | AB38: 0.451476 | AC38: 0.156693 | AD38: 0.2 | AE38: 1 | AF38: -0.118678 | AG38: PB | AH38: 2D compartment | AI38: 1 | AO38: 0 | AP38: 2 | AQ38: LPO | AR38: Lake_Pontchartrain | AS38: 80902010206 | AT38: Ponchitalawa Creek-Tchefuncta River | AU38: 36 | AV38: 1 | AW38: 1 | AX38: 36 | AY38: 0.299866 | AZ38: 0.332799 | BA38: 0.355836 | BB38: 0.375515 | BC38: 0.391797 | BD38: 0.424416 | BE38: 0.484452 | BF38: 11178400
A39: 36 | B39: Polygon ZM | C39: 37 | D39: 876904702 | E39: 0.994507 | F39: 0.001874 | G39: 0.003619 | H39: 1780200 | I39: 0 | J39: -4.139349 | K39: 0.05 | L39: 0.835 | M39: 10 | N39: 0.25 | O39: 0 | P39: 37 | Q39: 37 | R39: 1 | S39: 0.023 | T39: 0.001 | U39: 1 | V39: 0 | W39: 0.008 | X39: 0.05 | Y39: 0.05 | Z39: 0.018745 | AA39: -9999 | AB39: 0.596041 | AC39: 0.533795 | AD39: 0.2 | AE39: 1 | AF39: -0.601418 | AG39: PB | AH39: 2D tributary boundary (Qmult > 0) | AI39: 1 | AL39: S/SW Lake Pontch ungaged drainage | AM39: 32 + 33 | AN39: 0.5 + 1 | AO39: 0 | AP39: 2 | AQ39: LPO | AR39: Lake_Pontchartrain | AS39: 80902020100 | AU39: 37 | AV39: 1 | AW39: 1 | AX39: 37 | AY39: -0.074437 | AZ39: -0.005377 | BA39: 0.195124 | BB39: 0.378412 | BC39: 0.476285 | BD39: 0.576032 | BE39: 0.707139 | BF39: 876905000
A40: 37 | B40: Polygon ZM | C40: 38 | D40: 672883641 | E40: 0.989825 | F40: 0.007765 | G40: 0.00241 | H40: 1368000 | I40: 0 | J40: -4.78347 | K40: 0.05 | L40: 0.835 | M40: 10 | N40: 0.25 | O40: 0 | P40: 38 | Q40: 38 | R40: 1 | S40: 0.023 | T40: 0.001 | U40: 1 | V40: 0 | W40: 0.008 | X40: 0.05 | Y40: 0.05 | Z40: 0.028301 | AA40: -9999 | AB40: 0.270123 | AC40: 1.17017 | AD40: 0.2 | AE40: 1 | AF40: -0.488016 | AG40: PB | AH40: 2D tributary boundary (Qmult > 0) | AI40: 1 | AL40: SE/S Lake Pontch ungaged drainage | AM40: 31 + 32 | AN40: 1 + 0.5 | AO40: 0 | AP40: 2 | AQ40: LPO | AR40: Lake_Pontchartrain | AS40: 80902020100 | AU40: 38 | AV40: 1 | AW40: 1 | AX40: 38 | AY40: -0.338666 | AZ40: -0.217893 | BA40: -0.1184 | BB40: -0.042445 | BC40: 0.011124 | BD40: 0.124613 | BE40: 0.463838 | BF40: 672884000
...
